Workbook

Sheet EQUIPO ENERO 2025
C1: SOLUCIONES EXACTAS, S.A. | AQ1: Codigo: FO-SE-053 | AU1: Codigo: FO-SE-053
C3: LISTADO INVENTARIO BODEGAS | AQ3: Versión: 02 | AU3: Versión: 02
A4: No. | B4: PRODUCTO | C4: No. BODEGA | D4: MARCA | E4: MODELO | F4: CAPACIDAD | G4: IMAGEN | H4: PRECIO | I4: CODIGO INTERNO | J4: PROVEEDOR | K4: FECHA INGRESO BODEGA | L4: FACTURA No. PROVEEDOR | M4: BOLETA INGRESO BODEGA | N4: OBSERVACION | O4: VIENE MES ANTERIOR | P4: EXISTENCIA INICIO SEMANA | U4: INGRESO POR IMPORTACION O COMPRA | Z4: DESCARGA Y/O SALIDA | AE4: DEVOLUCIONES | AJ4: EXISTENCIA POR SEMANA | AO4: DEMO | AP4: TOTAL EXISTENCIA MENSUAL | AQ4: FACTURA VENTA | AR4: BOLETA DE SALIDA | AS4: ENVIO | AT4: FIRMA ULTIMO INVENTARIO | AU4: FECHA ULTIMA REVISION
P5: 1 | Q5: 2 | R5: 3 | S5: 4 | T5: 5 | U5: 1 | V5: 2 | W5: 3 | X5: 4 | Y5: 5 | Z5: 1 | AA5: 2 | AB5: 3 | AC5: 4 | AD5: 5 | AE5: 1 | AF5: 2 | AG5: 3 | AH5: 4 | AI5: 5 | AJ5: 1 | AK5: 2 | AL5: 3 | AM5: 4 | AN5: 5
A6: 1 | B6: ADAPTADOR PARA INDICADOR 9V1.2A MODELO: KEERDA | C6: No. 2 | D6: KEERDA | E6: DZ012ELL090120U | F6: 9V | G6: #VALUE! | H6: 395 | I6: SE-ADAT9V | J6: SIZEIN | K6: 45666 | L6: LK24112701 | M6: 118 | N6: 1 IVAN LEIVA/ 2 JESUS LORENZANA//1-PANTALEON//COPASA 4 | O6: 5 | P6: =O6 -> 5 | Q6: =AJ6 -> 54 | R6: =AK6 -> 51 | S6: =AL6 -> 51 | T6: =AM6 -> 47 | U6: 50 | Z6: 1 | AA6: 3 | AC6: 4 | AJ6: =P6-Z6+AE6+U6 -> 54 | AK6: =Q6-AA6+AF6+V6 -> 51 | AL6: =R6-AB6+AG6+W6 -> 51 | AM6: =S6-AC6+AH6+X6 -> 47 | AN6: =T6-AD6+AI6+Y6 -> 47 | AP6: =AN6 -> 47 | AQ6: 2364686916 | AR6: 244/253//268//292 | AS6: E:4587-IVAN//E: -JESUS//E:-PANTALEON
A7: =+A6+1 -> 2 | AP7: =AN7 -> 0
A8: =+A7+1 -> 3 | B8: ADAPTADORES GENERICOS 5 V 1 AMP AC/DC | C8: No. 2 | D8: BRECKNELL | E8: S/M | G8: #VALUE! | I8: SE-ADAP-1 AMP | J8: BRECKNELL | K8: 44592 | O8: 2 | P8: =O8 -> 2 | Q8: =AJ8 -> 2 | R8: =AK8 -> 2 | S8: =AL8 -> 2 | T8: =AM8 -> 2 | AJ8: =P8-Z8+AE8+U8 -> 2 | AK8: =Q8-AA8+AF8+V8 -> 2 | AL8: =R8-AB8+AG8+W8 -> 2 | AM8: =S8-AC8+AH8+X8 -> 2 | AN8: =T8-AD8+AI8+Y8 -> 2 | AP8: =AN8 -> 2
A9: =+A8+1 -> 4 | B9: ADAPTADORES SBI 505 ORIGINAL AWT05-505896 | C9: No. 2 | D9: AVERY WEIGH TRONIX | E9: AWT05-505896 | G9: #VALUE! | H9: 550 | I9: SE-ADAP-SBI505 | J9: AVERY WEIGH TRONIX | K9: 44592 | O9: 8 | P9: =O9 -> 8 | Q9: =AJ9 -> 8 | R9: =AK9 -> 8 | S9: =AL9 -> 8 | T9: =AM9 -> 8 | AJ9: =P9-Z9+AE9+U9 -> 8 | AK9: =Q9-AA9+AF9+V9 -> 8 | AL9: =R9-AB9+AG9+W9 -> 8 | AM9: =S9-AC9+AH9+X9 -> 8 | AN9: =T9-AD9+AI9+Y9 -> 8 | AP9: =AN9 -> 8
A10: =+A9+1 -> 5 | B10: ADAPTADOR BI 12T | C10: No. 2 | D10: BRECKNELL | E10: BI 12T | F10: 12t | G10: #VALUE! | I10: SE-ADAP-BI-12T | J10: BRECKNELL | K10: 44592 | O10: 1 | P10: =O10 -> 1 | Q10: =AJ10 -> 1 | R10: =AK10 -> 1 | S10: =AL10 -> 1 | T10: =AM10 -> 1 | AJ10: =P10-Z10+AE10+U10 -> 1 | AK10: =Q10-AA10+AF10+V10 -> 1 | AL10: =R10-AB10+AG10+W10 -> 1 | AM10: =S10-AC10+AH10+X10 -> 1 | AN10: =T10-AD10+AI10+Y10 -> 1 | AP10: =AN10 -> 1
A11: =+A10+1 -> 6 | B11: ADAPTADOR DE MODULOS INALAMBRICOS SE-7660 | C11: No.2 | E11: SE-ADAPT-7660 | G11: #VALUE! | J11: LOCOSC | K11: 45464 | M11: 87 | O11: 2 | P11: =O11 -> 2 | Q11: =AJ11 -> 2 | R11: =AK11 -> 2 | S11: =AL11 -> 2 | T11: =AM11 -> 2 | AJ11: =P11-Z11+AE11+U11 -> 2 | AK11: =Q11-AA11+AF11+V11 -> 2 | AL11: =R11-AB11+AG11+W11 -> 2 | AM11: =S11-AC11+AH11+X11 -> 2 | AN11: =T11-AD11+AI11+Y11 -> 2 | AP11: =AN11 -> 2
A12: =+A11+1 -> 7 | B12: ADAPTADOR DE CORRIENTE DE INDICADOR SE7517/ REPARADO DE CABLE | C12: NO.2 | D12: KEERDA | E12: DZ007AHL050100U | F12: 5.0V/1.0Ah | I12: SE-DZ007 | J12: LOCOSC | M12: 113 | O12: 1 | P12: =O12 -> 1 | Q12: =AJ12 -> 1 | R12: =AK12 -> 1 | S12: =AL12 -> 1 | T12: =AM12 -> 1 | AJ12: =P12-Z12+AE12+U12 -> 1 | AK12: =Q12-AA12+AF12+V12 -> 1 | AL12: =R12-AB12+AG12+W12 -> 1 | AM12: =S12-AC12+AH12+X12 -> 1 | AN12: =T12-AD12+AI12+Y12 -> 1 | AP12: =AN12 -> 1
A13: =+A12+1 -> 8 | B13: ADAPTADORES DE CORRIENTE PARA MODULOS INALAMBRICOS SE-7519A | C13: NO.2 | D13: S/M | E13: ZF120A-0421000 | F13: 4.2V/10A | G13: #VALUE! | I13: SE-ADAP-A | J13: LOCOSC | K13: 45582 | M13: 81 | O13: 2 | P13: =O13 -> 2 | Q13: =AJ13 -> 2 | R13: =AK13 -> 2 | S13: =AL13 -> 2 | T13: =AM13 -> 2 | AJ13: =P13-Z13+AE13+U13 -> 2 | AK13: =Q13-AA13+AF13+V13 -> 2 | AL13: =R13-AB13+AG13+W13 -> 2 | AM13: =S13-AC13+AH13+X13 -> 2 | AN13: =T13-AD13+AI13+Y13 -> 2 | AP13: =AN13 -> 2
A14: =+A13+1 -> 9 | B14: ARMARIOS ELECTRICOS ST4-420 | C14: No. 2 | D14: BRECKNELL | E14: ST4-420 | G14: #VALUE! | I14: SE-ARMAELEC | J14: BRECKNELL | K14: 44592 | O14: 3 | P14: =O14 -> 3 | Q14: =AJ14 -> 3 | R14: =AK14 -> 3 | S14: =AL14 -> 3 | T14: =AM14 -> 3 | AJ14: =P14-Z14+AE14+U14 -> 3 | AK14: =Q14-AA14+AF14+V14 -> 3 | AL14: =R14-AB14+AG14+W14 -> 3 | AM14: =S14-AC14+AH14+X14 -> 3 | AN14: =T14-AD14+AI14+Y14 -> 3 | AP14: =AN14 -> 3
A15: =+A14+1 -> 10 | B15: ARGOLLAS PARA BÁSCULAS PESA EJES | C15: NO.2 | D15: S/M | E15: M-20 | F15: S/C | G15: #VALUE! | I15: SE-ARG-PPEJES | J15: LOCOSC | K15: 45673 | L15: 240907-1 | M15: 131 | N15: 4-YEGUADA | O15: 0 | P15: =O15 -> 0 | Q15: =AJ15 -> 0 | R15: =AK15 -> 0 | S15: =AL15 -> 0 | T15: =AM15 -> 0 | W15: 4 | AB15: 4 | AJ15: =P15-Z15+AE15+U15 -> 0 | AK15: =Q15-AA15+AF15+V15 -> 0 | AL15: =R15-AB15+AG15+W15 -> 0 | AM15: =S15-AC15+AH15+X15 -> 0 | AN15: =T15-AD15+AI15+Y15 -> 0 | AP15: =AN15 -> 0 | AR15: 285
A16: =+A15+1 -> 11 | B16: BALANZA DE BOLSILLO CAPACIDAD DE 200x0.01g | C16: No. 1 | E16: HY-YH-J100120 | F16: 2 000 x 0.01 g | G16: #VALUE! | H16: 150 | I16: SE-FAB-GUA | K16: 44592 | O16: 5 | P16: =O16 -> 5 | Q16: =AJ16 -> 5 | R16: =AK16 -> 5 | S16: =AL16 -> 5 | T16: =AM16 -> 5 | AJ16: =P16-Z16+AE16+U16 -> 5 | AK16: =Q16-AA16+AF16+V16 -> 5 | AL16: =R16-AB16+AG16+W16 -> 5 | AM16: =S16-AC16+AH16+X16 -> 5 | AN16: =T16-AD16+AI16+Y16 -> 5 | AP16: =AN16 -> 5
A17: =+A16+1 -> 12 | B17: BALANZA DE LABORATORIO 1 000 x0.01g | C17: N/A | D17: ELECTRONIC BALANCE | E17: SE10002K | F17: 1 000 x 0.01 g | G17: #VALUE! | H17: 9180 | I17: SE-WTB1002K | J17: LOCOSC | K17: 45316 | M17: 15 | O17: 0 | P17: =O17 -> 0 | Q17: =AJ17 -> 0 | R17: =AK17 -> 0 | S17: =AL17 -> 0 | T17: =AM17 -> 0 | AJ17: =P17-Z17+AE17+U17 -> 0 | AK17: =Q17-AA17+AF17+V17 -> 0 | AL17: =R17-AB17+AG17+W17 -> 0 | AM17: =S17-AC17+AH17+X17 -> 0 | AN17: =T17-AD17+AI17+Y17 -> 0 | AP17: =AN17 -> 0
A18: =+A17+1 -> 13 | B18: BALANZA DE LABORATORIO 10000x0.1g | C18: No. 1 | D18: ELECTRONIC BALANCE | E18: SE-WT100001X | F18: 1 000 x 0.1 g | G18: #VALUE! | H18: 4600 | I18: SE-WT100001X | J18: LOCOSC | K18: 45216 | L18: 2015 | M18: 451 | O18: 0 | P18: =O18 -> 0 | Q18: =AJ18 -> 0 | R18: =AK18 -> 0 | S18: =AL18 -> 0 | T18: =AM18 -> 0 | AJ18: =P18-Z18+AE18+U18 -> 0 | AK18: =Q18-AA18+AF18+V18 -> 0 | AL18: =R18-AB18+AG18+W18 -> 0 | AM18: =S18-AC18+AH18+X18 -> 0 | AN18: =T18-AD18+AI18+Y18 -> 0 | AP18: =AN18 -> 0
A19: =+A18+1 -> 14 | B19: BALANZA DE LABORATORIO 1500g x 0.5g | C19: N/A | D19: ELECTRONIC BALANCE | E19: SE-WT15002KF | F19: 1 500 x 0.05 kg | G19: #VALUE! | H19: 2800 | I19: SE-WT15002KF-5 | J19: LOCOSC | K19: 45107 | L19: LP230224-1 | M19: 393 | O19: 5 | P19: =O19 -> 5 | Q19: =AJ19 -> 5 | R19: =AK19 -> 5 | S19: =AL19 -> 5 | T19: =AM19 -> 5 | AJ19: =P19-Z19+AE19+U19 -> 5 | AK19: =Q19-AA19+AF19+V19 -> 5 | AL19: =R19-AB19+AG19+W19 -> 5 | AM19: =S19-AC19+AH19+X19 -> 5 | AN19: =T19-AD19+AI19+Y19 -> 5 | AP19: =AN19 -> 5
A20: =+A19+1 -> 15 | B20: BALANZA DE LABORATORIO CAPACIDAD 15 kg x 0.1g | C20: No. 1 | D20: ELECTRONIC BALANCE | E20: SE150001XD | F20: 15 kg x 0.1 g | G20: #VALUE! | H20: 9180 | I20: SE-WT150001XD | J20: LOCOSC | K20: 45316 | M20: 15 | O20: 0 | P20: =O20 -> 0 | Q20: =AJ20 -> 0 | R20: =AK20 -> 0 | S20: =AL20 -> 0 | T20: =AM20 -> 0 | AJ20: =P20-Z20+AE20+U20 -> 0 | AK20: =Q20-AA20+AF20+V20 -> 0 | AL20: =R20-AB20+AG20+W20 -> 0 | AM20: =S20-AC20+AH20+X20 -> 0 | AN20: =T20-AD20+AI20+Y20 -> 0 | AP20: =AN20 -> 0
A21: =+A20+1 -> 16 | B21: BALANZA DE LABORATORIO CAPACIDAD 300 g x 1 mg | C21: N/A | D21: ELECTRONIC BALANCE | E21: SE-3003GH | F21: 300 g x 1 mg | G21: #VALUE! | H21: 36300 | I21: SE3003GH | J21: LOCOSC | K21: 45299 | M21: 6 | O21: 0 | P21: =O21 -> 0 | Q21: =AJ21 -> 0 | R21: =AK21 -> 0 | S21: =AL21 -> 0 | T21: =AM21 -> 0 | AJ21: =P21-Z21+AE21+U21 -> 0 | AK21: =Q21-AA21+AF21+V21 -> 0 | AL21: =R21-AB21+AG21+W21 -> 0 | AM21: =S21-AC21+AH21+X21 -> 0 | AN21: =T21-AD21+AI21+Y21 -> 0 | AP21: =AN21 -> 0
A22: =+A21+1 -> 17 | B22: BALANZA ANALITICA CAPACIDAD DE 5 000g x 0.01 g | C22: N/A | D22: ELECTRONIC BALANCE | E22: SE-5 0002CF | F22: 5 000 x 0.01 g | G22: #VALUE! | I22: SE50002CF | J22: LOCOSC | K22: 45336 | L22: 669885E9 | M22: 37 | O22: 0 | P22: =O22 -> 0 | Q22: =AJ22 -> 0 | R22: =AK22 -> 0 | S22: =AL22 -> 0 | T22: =AM22 -> 0 | AJ22: =P22-Z22+AE22+U22 -> 0 | AK22: =Q22-AA22+AF22+V22 -> 0 | AL22: =R22-AB22+AG22+W22 -> 0 | AM22: =S22-AC22+AH22+X22 -> 0 | AN22: =T22-AD22+AI22+Y22 -> 0 | AP22: =AN22 -> 0
A23: =+A22+1 -> 18 | B23: BALANZA ANALITICA CAPACIDAD DE 1 000 g x 20 mg | C23: N/A | D23: ELECTRONIC BALANCE | E23: SE-10003N | F23: 1 000 g x 20 mg | G23: #VALUE! | I23: SE10003N | J23: LOCOSC | K23: 45336 | L23: 669885E9 | M23: 37 | O23: 0 | P23: =O23 -> 0 | Q23: =AJ23 -> 0 | R23: =AK23 -> 0 | S23: =AL23 -> 0 | T23: =AM23 -> 0 | AJ23: =P23-Z23+AE23+U23 -> 0 | AK23: =Q23-AA23+AF23+V23 -> 0 | AL23: =R23-AB23+AG23+W23 -> 0 | AM23: =S23-AC23+AH23+X23 -> 0 | AN23: =T23-AD23+AI23+Y23 -> 0 | AP23: =AN23 -> 0
A24: =+A23+1 -> 19 | B24: BALANZA ANALITICA CAPACIDAD DE 210 g x 10 mg | C24: N/A | D24: ELECTRONIC BALANCE | E24: SE-2085A | F24: 210 g x 10 mg | G24: #VALUE! | I24: SE2085A | J24: LOCOSC | K24: 45336 | L24: 669885E9 | M24: 38 | O24: 0 | P24: =O24 -> 0 | Q24: =AJ24 -> 0 | R24: =AK24 -> 0 | S24: =AL24 -> 0 | T24: =AM24 -> 0 | AJ24: =P24-Z24+AE24+U24 -> 0 | AK24: =Q24-AA24+AF24+V24 -> 0 | AL24: =R24-AB24+AG24+W24 -> 0 | AM24: =S24-AC24+AH24+X24 -> 0 | AN24: =T24-AD24+AI24+Y24 -> 0 | AP24: =AN24 -> 0
A25: =+A24+1 -> 20 | B25: BALANZA DE LABORATORIO CAPACIDAD 420 x 0.001g LUNA | C25: No.1 | E25: SE-LPB423E | F25: 420 x 0.001 g | G25: #VALUE! | I25: LPB423E | J25: ADAM | K25: 45454 | L25: 34687-035292 | M25: 76 | O25: 0 | P25: =O25 -> 0 | Q25: =AJ25 -> 0 | R25: =AK25 -> 0 | S25: =AL25 -> 0 | T25: =AM25 -> 0 | AJ25: =P25-Z25+AE25+U25 -> 0 | AK25: =Q25-AA25+AF25+V25 -> 0 | AL25: =R25-AB25+AG25+W25 -> 0 | AM25: =S25-AC25+AH25+X25 -> 0 | AN25: =T25-AD25+AI25+Y25 -> 0 | AP25: =AN25 -> 0
A26: =+A25+1 -> 21 | B26: BÁSCULA DE MESA | C26: No. 1 | D26: BRECKNELL | E26: SE-7680W | F26: 3 x 0.005 kg | G26: #VALUE! | H26: 2800 | I26: SE-LP7680-3Kg | J26: LOCOSC | K26: 45574 | L26: LP3211240 | M26: 71 | O26: 8 | P26: =O26 -> 8 | Q26: =AJ26 -> 8 | R26: =AK26 -> 8 | S26: =AL26 -> 8 | T26: =AM26 -> 8 | AJ26: =P26-Z26+AE26+U26 -> 8 | AK26: =Q26-AA26+AF26+V26 -> 8 | AL26: =R26-AB26+AG26+W26 -> 8 | AM26: =S26-AC26+AH26+X26 -> 8 | AN26: =T26-AD26+AI26+Y26 -> 8 | AP26: =AN26 -> 8
A27: =+A26+1 -> 22 | B27: BÁSCULA DE MESA | C27: No. 1 | D27: BRECKNELL | E27: SE-7680W | F27: 6 x 0.001 kg | G27: #VALUE! | H27: 2800 | I27: SE-LP7680-6Kg | J27: LOCOSC | K27: 45574 | L27: LP3211240 | M27: 71 | O27: 10 | P27: =O27 -> 10 | Q27: =AJ27 -> 10 | R27: =AK27 -> 10 | S27: =AL27 -> 10 | T27: =AM27 -> 10 | AJ27: =P27-Z27+AE27+U27 -> 10 | AK27: =Q27-AA27+AF27+V27 -> 10 | AL27: =R27-AB27+AG27+W27 -> 10 | AM27: =S27-AC27+AH27+X27 -> 10 | AN27: =T27-AD27+AI27+Y27 -> 10 | AP27: =AN27 -> 10
A28: =+A27+1 -> 23 | B28: BÁSCULA DE MESA | C28: No. 1 | D28: BRECKNELL | E28: SE-7680W | F28: 15 x 0.002 kg | G28: #VALUE! | H28: 2800 | I28: SE-LP7680-15Kg | J28: LOCOSC | K28: 45574 | L28: LP3211240 | M28: 71 | N28: 1-RESTAURANTE NEREA// 1 BASCULA PPAPIS BBQ S: 23032003005 | O28: 8 | P28: =O28 -> 8 | Q28: =AJ28 -> 8 | R28: =AK28 -> 7 | S28: =AL28 -> 7 | T28: =AM28 -> 7 | AA28: 1 | AD28: 1 | AJ28: =P28-Z28+AE28+U28 -> 8 | AK28: =Q28-AA28+AF28+V28 -> 7 | AL28: =R28-AB28+AG28+W28 -> 7 | AM28: =S28-AC28+AH28+X28 -> 7 | AN28: =T28-AD28+AI28+Y28 -> 6 | AP28: =AN28 -> 6 | AQ28: 4147989008 | AR28: 257// 313-PPAPIS | AS28: W:4596-NEREA
A29: =+A28+1 -> 24 | B29: BASCULA DE MESA MODELO SE-7680W | C29: No. 1 | D29: BRECKNELL | E29: SE-7680W | F29: 30 x 0.005 kg | G29: #VALUE! | H29: 3000 | I29: SE-LP7680-30kg | J29: LOCOSC | K29: 45107 | L29: LP230224-1 | M29: 390 | O29: 5 | P29: =O29 -> 5 | Q29: =AJ29 -> 5 | R29: =AK29 -> 5 | S29: =AL29 -> 5 | T29: =AM29 -> 5 | AJ29: =P29-Z29+AE29+U29 -> 5 | AK29: =Q29-AA29+AF29+V29 -> 5 | AL29: =R29-AB29+AG29+W29 -> 5 | AM29: =S29-AC29+AH29+X29 -> 5 | AN29: =T29-AD29+AI29+Y29 -> 5 | AP29: =AN29 -> 5
A30: =+A29+1 -> 25 | B30: BALANZA ELECTRONIC BALANCE MODELO SE-2003CH DE 2000gx1mg | C30: N/A | D30: ELECTRONIC BALANCE | E30: SE-2003CH | F30: 200 x 1 mg | G30: #VALUE! | H30: 6300 | I30: SE-2003CH | J30: LOCOSC | K30: 45139 | L30: 781781092133 | M30: 419 | O30: 0 | P30: =O30 -> 0 | Q30: =AJ30 -> 0 | R30: =AK30 -> 0 | S30: =AL30 -> 0 | T30: =AM30 -> 0 | AJ30: =P30-Z30+AE30+U30 -> 0 | AK30: =Q30-AA30+AF30+V30 -> 0 | AL30: =R30-AB30+AG30+W30 -> 0 | AM30: =S30-AC30+AH30+X30 -> 0 | AN30: =T30-AD30+AI30+Y30 -> 0 | AP30: =AN30 -> 0
A31: =+A30+1 -> 26 | B31: BASES DE CELDA DE CARGA PARA CELDAS DE ACEROS DE GUATEMALA | C31: NO. 2 | D31: S/M | E31: S/M | G31: #VALUE! | K31: 45568 | M31: 62 | O31: 2 | P31: =O31 -> 2 | Q31: =AJ31 -> 2 | R31: =AK31 -> 2 | S31: =AL31 -> 2 | T31: =AM31 -> 2 | AJ31: =P31-Z31+AE31+U31 -> 2 | AK31: =Q31-AA31+AF31+V31 -> 2 | AL31: =R31-AB31+AG31+W31 -> 2 | AM31: =S31-AC31+AH31+X31 -> 2 | AN31: =T31-AD31+AI31+Y31 -> 2 | AP31: =AN31 -> 2
A32: =+A31+1 -> 27 | B32: BASCULA COLGANTE CAPACIDAD 5 t LP7650G | C32: NO.2 | D32: BRECKNELL | E32: SE-7650 | F32: 5 T | G32: #VALUE! | H32: 9500 | I32: SE-LP7650G-5T | J32: SIZEN | K32: 45666 | L32: LK24112701 | M32: 117 | N32: 1-ACEROS DE GUATEMALA | O32: 0 | P32: =O32 -> 0 | Q32: =AJ32 -> 2 | R32: =AK32 -> 1 | S32: =AL32 -> 1 | T32: =AM32 -> 1 | U32: 2 | AA32: 1 | AJ32: =P32-Z32+AE32+U32 -> 2 | AK32: =Q32-AA32+AF32+V32 -> 1 | AL32: =R32-AB32+AG32+W32 -> 1 | AM32: =S32-AC32+AH32+X32 -> 1 | AN32: =T32-AD32+AI32+Y32 -> 1 | AP32: =AN32 -> 1 | AQ32: 837175793 | AR32: 262 | AS32: E:4608-AG
A33: =+A32+1 -> 28 | B33: BASCULA COLGANTE CAPACIDAD 10 t LP7650G | C33: No. 2 | D33: BRECKNELL | E33: SE-7650 | F33: 10 t | G33: #VALUE! | H33: Q16,800.00 Consultar primero | I33: SE-LP7650G-10T | J33: LOCOSC | K33: 45107 | L33: LP230224-1 | M33: 393 | O33: 1 | P33: =O33 -> 1 | Q33: =AJ33 -> 1 | R33: =AK33 -> 1 | S33: =AL33 -> 1 | T33: =AM33 -> 1 | AJ33: =P33-Z33+AE33+U33 -> 1 | AK33: =Q33-AA33+AF33+V33 -> 1 | AL33: =R33-AB33+AG33+W33 -> 1 | AM33: =S33-AC33+AH33+X33 -> 1 | AN33: =T33-AD33+AI33+Y33 -> 1 | AP33: =AN33 -> 1
A34: =+A33+1 -> 29 | B34: BASCULA COLGANTE CAPACIDAD 300kg LP7652G | C34: No. 1 | D34: BRECKNELL | E34: SE-7652 | F34: 300 x 0.1 kg | G34: #VALUE! | H34: 650 | I34: SE-COLG-LP7652G | J34: LOCOSC | K34: 45107 | L34: LP230224-1 | M34: 389 | N34: 1-JACOBO VILLEDA//1-JACOBO | O34: 13 | P34: =O34 -> 13 | Q34: =AJ34 -> 13 | R34: =AK34 -> 12 | S34: =AL34 -> 11 | T34: =AM34 -> 11 | AA34: 1 | AB34: 1 | AJ34: =P34-Z34+AE34+U34 -> 13 | AK34: =Q34-AA34+AF34+V34 -> 12 | AL34: =R34-AB34+AG34+W34 -> 11 | AM34: =S34-AC34+AH34+X34 -> 11 | AN34: =T34-AD34+AI34+Y34 -> 11 | AP34: =AN34 -> 11 | AR34: 271//274 | AS34: E:4603-JACOBO//E:470-JACOBO
A35: =+A34+1 -> 30 | B35: BASCULA COLGANTE PANTALLA LED DE 5 DIGITOS | C35: No. 1 | D35: BRECKNELL | E35: SE-7561 | F35: 300 x 0.1 kg | G35: #VALUE! | H35: 1800 | I35: SE-LP7561E | J35: LOCOSC | K35: 44592 | N35: 1-CARLOS PEREZ | O35: 7 | P35: =O35 -> 7 | Q35: =AJ35 -> 7 | R35: =AK35 -> 7 | S35: =AL35 -> 6 | T35: =AM35 -> 6 | AB35: 1 | AJ35: =P35-Z35+AE35+U35 -> 7 | AK35: =Q35-AA35+AF35+V35 -> 7 | AL35: =R35-AB35+AG35+W35 -> 6 | AM35: =S35-AC35+AH35+X35 -> 6 | AN35: =T35-AD35+AI35+Y35 -> 6 | AP35: =AN35 -> 6 | AR35: 282 | AS35: E:4611-CARLOS
A36: =+A35+1 -> 31 | B36: BASCULA DE MESA CAPACIDAD 30kgx1g | C36: No. 1 | D36: ELECTRONIC BALANCE | E36: SE-WT300001X | F36: 30 kg x 1 g | G36: #VALUE! | H36: 3400 | I36: SE-WT300001X | J36: LOCOSC | K36: 45107 | L36: LP230224-1 | M36: 393 | O36: 4 | P36: =O36 -> 4 | Q36: =AJ36 -> 4 | R36: =AK36 -> 4 | S36: =AL36 -> 4 | T36: =AM36 -> 4 | AJ36: =P36-Z36+AE36+U36 -> 4 | AK36: =Q36-AA36+AF36+V36 -> 4 | AL36: =R36-AB36+AG36+W36 -> 4 | AM36: =S36-AC36+AH36+X36 -> 4 | AN36: =T36-AD36+AI36+Y36 -> 4 | AP36: =AN36 -> 4
A37: =+A36+1 -> 32 | B37: BASCULA DE MESA MODELO SE-Y2-208 CAPACIDAD 40kg X 5g | C37: No. 1 | D37: TECNO SCALE | E37: SE-Y2-208 | F37: 40 kg x 5 g | G37: #VALUE! | H37: 550 | I37: SE-Y2-208 | J37: LOCOSC | K37: 45328 | L37: LP230224-1 | M37: 32 | O37: 14 | P37: =O37 -> 14 | Q37: =AJ37 -> 14 | R37: =AK37 -> 14 | S37: =AL37 -> 14 | T37: =AM37 -> 14 | AJ37: =P37-Z37+AE37+U37 -> 14 | AK37: =Q37-AA37+AF37+V37 -> 14 | AL37: =R37-AB37+AG37+W37 -> 14 | AM37: =S37-AC37+AH37+X37 -> 14 | AN37: =T37-AD37+AI37+Y37 -> 14 | AP37: =AN37 -> 14
A38: =+A37+1 -> 33 | B38: BASCULA DE PISO ACERO INOXIDABLE CAPACIDAD 150kg DE 40X50 | C38: No. 1 | D38: BRECKNELL | E38: SE-7610W | F38: 150 x 0.02 kg | G38: #VALUE! | H38: 7500 | I38: SE-7510W-150kg | J38: LOCOSC | K38: 45107 | L38: LP230224-1 | M38: 392 | O38: 5 | P38: =O38 -> 5 | Q38: =AJ38 -> 5 | R38: =AK38 -> 5 | S38: =AL38 -> 5 | T38: =AM38 -> 5 | AJ38: =P38-Z38+AE38+U38 -> 5 | AK38: =Q38-AA38+AF38+V38 -> 5 | AL38: =R38-AB38+AG38+W38 -> 5 | AM38: =S38-AC38+AH38+X38 -> 5 | AN38: =T38-AD38+AI38+Y38 -> 5 | AO38: 1 | AP38: =AN38 -> 5
A39: =+A38+1 -> 34 | B39: BÁSCULA DE PISO SS ACERO INOXIDABLE CAPACIDAD 150 kg DE 60 x 60 cm | C39: NO. 1 | D39: BRECKNELL | E39: SE-7610WSS | F39: 150 x 0.02 kg | G39: #VALUE! | H39: 10800 | I39: SE7610W-SS-6060-150kg | J39: LOCOSC | K39: 45673 | L39: 240907-1 | M39: 126 | N39: SALE A DEMOSTRACION SERIE: 0241013005 | O39: 0 | P39: =O39 -> 0 | Q39: =AJ39 -> 0 | R39: =AK39 -> 0 | S39: =AL39 -> 5 | T39: =AM39 -> 5 | W39: 5 | AJ39: =P39-Z39+AE39+U39 -> 0 | AK39: =Q39-AA39+AF39+V39 -> 0 | AL39: =R39-AB39+AG39+W39 -> 5 | AM39: =S39-AC39+AH39+X39 -> 5 | AN39: =T39-AD39+AI39+Y39 -> 5 | AO39: 1 | AP39: =AN39 -> 5
A40: =+A39+1 -> 35 | B40: BASCULA DE PISO CAPACIDAD 30kg DE 40X40 | C40: No. 1 | D40: BRECKNELL | E40: SE-7610 | F40: 30 x 0.005 kg | G40: #VALUE! | H40: 2800 | I40: SE-LP7610-30kg | J40: LOCOSC | K40: 45574 | L40: LP3211240 | M40: 71 | O40: 8 | P40: =O40 -> 8 | Q40: =AJ40 -> 8 | R40: =AK40 -> 8 | S40: =AL40 -> 8 | T40: =AM40 -> 8 | AJ40: =P40-Z40+AE40+U40 -> 8 | AK40: =Q40-AA40+AF40+V40 -> 8 | AL40: =R40-AB40+AG40+W40 -> 8 | AM40: =S40-AC40+AH40+X40 -> 8 | AN40: =T40-AD40+AI40+Y40 -> 8 | AO40: 1 | AP40: =AN40 -> 8
A41: =+A40+1 -> 36 | B41: BASCULA DE PISO CAPACIDAD 60kg DE 40X50 | C41: No. 1 | D41: BRECKNELL | E41: SE-7610 | F41: 60 x 0.01 kg | G41: #VALUE! | H41: 2800 | I41: SE-LP7610-60kg | J41: LOCOSC | K41: 45574 | L41: LP3211240 | M41: 71 | O41: 2 | P41: =O41 -> 2 | Q41: =AJ41 -> 2 | R41: =AK41 -> 2 | S41: =AL41 -> 2 | T41: =AM41 -> 2 | AJ41: =P41-Z41+AE41+U41 -> 2 | AK41: =Q41-AA41+AF41+V41 -> 2 | AL41: =R41-AB41+AG41+W41 -> 2 | AM41: =S41-AC41+AH41+X41 -> 2 | AN41: =T41-AD41+AI41+Y41 -> 2 | AO41: 0 | AP41: =AN41 -> 2
...

Sheet EQUIPO FEBRERO 2025  1
B1: SOLUCIONES EXACTAS, S.A. | AR1: Codigo: FO-SE-053 | AV1: Codigo: FO-SE-053
B3: LISTADO INVENTARIO BODEGAS FEBRERO | AK3: FEBRERO | AR3: Versión: 02 | AV3: Versión: 02
A4: No. | B4: PRODUCTO | C4: No. BODEGA | D4: MARCA | E4: MODELO | F4: CAPACIDAD | G4: IMAGEN | H4: PRECIO | I4: CODIGO INTERNO | J4: PROVEEDOR | K4: FECHA INGRESO BODEGA | L4: FACTURA No. PROVEEDOR | M4: BOLETA INGRESO BODEGA | N4: OBSERVACION | O4: VIENE MES ANTERIOR | P4: EXISTENCIA INICIO SEMANA | U4: INGRESO POR IMPORTACION O COMPRA | Z4: DESCARGA Y/O SALIDA | AE4: DEVOLUCIONES | AJ4: INICIO DE MES | AK4: EXISTENCIA POR SEMANA | AP4: DEMO | AQ4: TOTAL EXISTENCIA MENSUAL | AR4: FACTURA VENTA | AS4: BOLETA DE SALIDA | AT4: ENVIO | AU4: FIRMA ULTIMO INVENTARIO | AV4: FECHA ULTIMA REVISION
P5: 1 | Q5: 2 | R5: 3 | S5: 4 | T5: 5 | U5: 1 | V5: 2 | W5: 3 | X5: 4 | Y5: 5 | Z5: 1 | AA5: 2 | AB5: 3 | AC5: 4 | AD5: 5 | AE5: 1 | AF5: 2 | AG5: 3 | AH5: 4 | AI5: 5 | AK5: 1 | AL5: 2 | AM5: 3 | AN5: 4 | AO5: 5
A6: 1 | B6: ADAPTADOR PARA INDICADOR 9V1.2A MODELO: KEERDA | C6: No. 2 | D6: KEERDA | E6: DZ012ELL090120U | F6: 9V | G6: #VALUE! | H6: 395 | I6: SE-ADAT9V | J6: SIZEIN | K6: 45666 | L6: LK24112701 | M6: 118 | N6: ctl/ALCSA/PANTALEON SE AGREGO 1 DEBIDO EN EL CUADRE FISICO CORREPONDE DE 43 | O6: ='EQUIPO ENERO 2025'!AP6 -> 47 | P6: =O6 -> 47 | Q6: =AK6 -> 45 | R6: =AL6 -> 44 | S6: =AM6 -> 43 | T6: =AN6 -> 43 | Z6: 6 | AA6: 10 | AB6: 5 | AC6: 1 | AE6: 4 | AF6: 9 | AG6: 4 | AH6: 1 | AJ6: ='EQUIPO ENERO 2025'!AP6 -> 47 | AK6: =P6-Z6+AE6+U6 -> 45 | AL6: =Q6-AA6+AF6+V6 -> 44 | AM6: =R6-AB6+AG6+W6 -> 43 | AN6: =S6-AC6+AH6+X6 -> 43 | AO6: =T6-AD6+AI6+Y6 -> 43 | AQ6: =AO6 -> 43 | AS6: 320/327/335/338/332
A7: =A6+1 -> 2 | B7: ADAPTADOR GENERICO 9V 600 mA | C7: No.2 | D7: Byp | F7: 9v | K7: 45712 | M7: 162 | O7: ='EQUIPO ENERO 2025'!AP7 -> 0 | P7: =O7 -> 0 | Q7: =AK7 -> 0 | R7: =AL7 -> 0 | S7: =AM7 -> 10 | T7: =AN7 -> 10 | W7: 10 | AK7: =P7-Z7+AE7+U7 -> 0 | AL7: =Q7-AA7+AF7+V7 -> 0 | AM7: =R7-AB7+AG7+W7 -> 10 | AN7: =S7-AC7+AH7+X7 -> 10 | AO7: =T7-AD7+AI7+Y7 -> 10 | AQ7: =AO7 -> 10
A8: =A7+1 -> 3 | B8: ADAPTADORES GENERICOS 5 V 1 AMP AC/DC | C8: No. 2 | D8: BRECKNELL | E8: S/M | G8: #VALUE! | I8: SE-ADAP-1 AMP | J8: BRECKNELL | K8: 44592 | O8: ='EQUIPO ENERO 2025'!AP8 -> 2 | P8: =O8 -> 2 | Q8: =AK8 -> 2 | R8: =AL8 -> 2 | S8: =AM8 -> 2 | T8: =AN8 -> 2 | AJ8: ='EQUIPO ENERO 2025'!AP8 -> 2 | AK8: =P8-Z8+AE8+U8 -> 2 | AL8: =Q8-AA8+AF8+V8 -> 2 | AM8: =R8-AB8+AG8+W8 -> 2 | AN8: =S8-AC8+AH8+X8 -> 2 | AO8: =T8-AD8+AI8+Y8 -> 2 | AQ8: =AO8 -> 2
A9: =A8+1 -> 4 | B9: ADAPTADORES SBI 505 ORIGINAL AWT05-505896 | C9: No. 2 | D9: AVERY WEIGH TRONIX | E9: AWT05-505896 | G9: #VALUE! | H9: 550 | I9: SE-ADAP-SBI505 | J9: AVERY WEIGH TRONIX | K9: 44592 | O9: ='EQUIPO ENERO 2025'!AP9 -> 8 | P9: =O9 -> 8 | Q9: =AK9 -> 8 | R9: =AL9 -> 8 | S9: =AM9 -> 8 | T9: =AN9 -> 8 | AJ9: ='EQUIPO ENERO 2025'!AP9 -> 8 | AK9: =P9-Z9+AE9+U9 -> 8 | AL9: =Q9-AA9+AF9+V9 -> 8 | AM9: =R9-AB9+AG9+W9 -> 8 | AN9: =S9-AC9+AH9+X9 -> 8 | AO9: =T9-AD9+AI9+Y9 -> 8 | AQ9: =AO9 -> 8
A10: =A9+1 -> 5 | B10: ADAPTADOR BI 12T | C10: No. 2 | D10: BRECKNELL | E10: BI 12T | F10: 12t | G10: #VALUE! | I10: SE-ADAP-BI-12T | J10: BRECKNELL | K10: 44592 | O10: ='EQUIPO ENERO 2025'!AP10 -> 1 | P10: =O10 -> 1 | Q10: =AK10 -> 1 | R10: =AL10 -> 1 | S10: =AM10 -> 1 | T10: =AN10 -> 1 | AJ10: ='EQUIPO ENERO 2025'!AP10 -> 1 | AK10: =P10-Z10+AE10+U10 -> 1 | AL10: =Q10-AA10+AF10+V10 -> 1 | AM10: =R10-AB10+AG10+W10 -> 1 | AN10: =S10-AC10+AH10+X10 -> 1 | AO10: =T10-AD10+AI10+Y10 -> 1 | AQ10: =AO10 -> 1
A11: =A10+1 -> 6 | B11: ADAPTADOR DE MODULOS INALAMBRICOS SE-7660 | C11: No.2 | E11: SE-ADAPT-7660 | G11: #VALUE! | J11: LOCOSC | K11: 45464 | M11: 87 | O11: ='EQUIPO ENERO 2025'!AP11 -> 2 | P11: =O11 -> 2 | Q11: =AK11 -> 2 | R11: =AL11 -> 2 | S11: =AM11 -> 2 | T11: =AN11 -> 2 | AJ11: ='EQUIPO ENERO 2025'!AP11 -> 2 | AK11: =P11-Z11+AE11+U11 -> 2 | AL11: =Q11-AA11+AF11+V11 -> 2 | AM11: =R11-AB11+AG11+W11 -> 2 | AN11: =S11-AC11+AH11+X11 -> 2 | AO11: =T11-AD11+AI11+Y11 -> 2 | AQ11: =AO11 -> 2
A12: =A11+1 -> 7 | B12: ADAPTADOR DE CORRIENTE DE INDICADOR SE7517/ REPARADO DE CABLE | C12: NO.2 | D12: KEERDA | E12: DZ007AHL050100U | F12: 5.0V/1.0Ah | I12: SE-DZ007 | J12: LOCOSC | M12: 113 | O12: ='EQUIPO ENERO 2025'!AP12 -> 1 | P12: =O12 -> 1 | Q12: =AK12 -> 1 | R12: =AL12 -> 1 | S12: =AM12 -> 1 | T12: =AN12 -> 1 | AJ12: ='EQUIPO ENERO 2025'!AP12 -> 1 | AK12: =P12-Z12+AE12+U12 -> 1 | AL12: =Q12-AA12+AF12+V12 -> 1 | AM12: =R12-AB12+AG12+W12 -> 1 | AN12: =S12-AC12+AH12+X12 -> 1 | AO12: =T12-AD12+AI12+Y12 -> 1 | AQ12: =AO12 -> 1
A13: =A12+1 -> 8 | B13: ADAPTADORES DE CORRIENTE PARA MODULOS INALAMBRICOS SE-7519A | C13: NO.2 | D13: S/M | E13: ZF120A-0421000 | F13: 4.2V/10A | G13: #VALUE! | I13: SE-ADAP-A | J13: LOCOSC | K13: 45582 | M13: 81 | O13: ='EQUIPO ENERO 2025'!AP13 -> 2 | P13: =O13 -> 2 | Q13: =AK13 -> 2 | R13: =AL13 -> 2 | S13: =AM13 -> 2 | T13: =AN13 -> 2 | AJ13: ='EQUIPO ENERO 2025'!AP13 -> 2 | AK13: =P13-Z13+AE13+U13 -> 2 | AL13: =Q13-AA13+AF13+V13 -> 2 | AM13: =R13-AB13+AG13+W13 -> 2 | AN13: =S13-AC13+AH13+X13 -> 2 | AO13: =T13-AD13+AI13+Y13 -> 2 | AQ13: =AO13 -> 2
A14: =A13+1 -> 9 | B14: ARMARIOS ELECTRICOS ST4-420 | C14: No. 2 | D14: BRECKNELL | E14: ST4-420 | G14: #VALUE! | I14: SE-ARMAELEC | J14: BRECKNELL | K14: 44592 | O14: ='EQUIPO ENERO 2025'!AP14 -> 3 | P14: =O14 -> 3 | Q14: =AK14 -> 3 | R14: =AL14 -> 3 | S14: =AM14 -> 3 | T14: =AN14 -> 3 | AJ14: ='EQUIPO ENERO 2025'!AP14 -> 3 | AK14: =P14-Z14+AE14+U14 -> 3 | AL14: =Q14-AA14+AF14+V14 -> 3 | AM14: =R14-AB14+AG14+W14 -> 3 | AN14: =S14-AC14+AH14+X14 -> 3 | AO14: =T14-AD14+AI14+Y14 -> 3 | AQ14: =AO14 -> 3
A15: =A14+1 -> 10 | B15: ARGOLLAS PARA BÁSCULAS PESA EJES | C15: NO.2 | D15: S/M | E15: M-20 | F15: S/C | G15: #VALUE! | I15: SE-ARG-PPEJES | J15: LOCOSC | K15: 45673 | L15: 240907-1 | M15: 131 | O15: ='EQUIPO ENERO 2025'!AP15 -> 0 | P15: =O15 -> 0 | Q15: =AK15 -> 0 | R15: =AL15 -> 0 | S15: =AM15 -> 0 | T15: =AN15 -> 0 | AJ15: ='EQUIPO ENERO 2025'!AP15 -> 0 | AK15: =P15-Z15+AE15+U15 -> 0 | AL15: =Q15-AA15+AF15+V15 -> 0 | AM15: =R15-AB15+AG15+W15 -> 0 | AN15: =S15-AC15+AH15+X15 -> 0 | AO15: =T15-AD15+AI15+Y15 -> 0 | AQ15: =AO15 -> 0
A16: =A15+1 -> 11 | B16: BALANZA DE BOLSILLO CAPACIDAD DE 200x0.01g | C16: No. 1 | E16: HY-YH-J100120 | F16: 2 000 x 0.01 g | G16: #VALUE! | H16: 150 | I16: SE-FAB-GUA | K16: 44592 | O16: ='EQUIPO ENERO 2025'!AP16 -> 5 | P16: =O16 -> 5 | Q16: =AK16 -> 5 | R16: =AL16 -> 5 | S16: =AM16 -> 5 | T16: =AN16 -> 5 | AJ16: ='EQUIPO ENERO 2025'!AP16 -> 5 | AK16: =P16-Z16+AE16+U16 -> 5 | AL16: =Q16-AA16+AF16+V16 -> 5 | AM16: =R16-AB16+AG16+W16 -> 5 | AN16: =S16-AC16+AH16+X16 -> 5 | AO16: =T16-AD16+AI16+Y16 -> 5 | AQ16: =AO16 -> 5
A17: =A16+1 -> 12 | B17: BALANZA DE LABORATORIO 1 000 x0.01g | C17: N/A | D17: ELECTRONIC BALANCE | E17: SE10002K | F17: 1 000 x 0.01 g | G17: #VALUE! | H17: 9180 | I17: SE-WTB1002K | J17: LOCOSC | K17: 45316 | M17: 15 | O17: ='EQUIPO ENERO 2025'!AP17 -> 0 | P17: =O17 -> 0 | Q17: =AK17 -> 0 | R17: =AL17 -> 0 | S17: =AM17 -> 0 | T17: =AN17 -> 0 | AJ17: ='EQUIPO ENERO 2025'!AP17 -> 0 | AK17: =P17-Z17+AE17+U17 -> 0 | AL17: =Q17-AA17+AF17+V17 -> 0 | AM17: =R17-AB17+AG17+W17 -> 0 | AN17: =S17-AC17+AH17+X17 -> 0 | AO17: =T17-AD17+AI17+Y17 -> 0 | AQ17: =AO17 -> 0
A18: =A17+1 -> 13 | B18: BALANZA DE LABORATORIO 10000x0.1g | C18: No. 1 | D18: ELECTRONIC BALANCE | E18: SE-WT100001X | F18: 1 000 x 0.1 g | G18: #VALUE! | H18: 4600 | I18: SE-WT100001X | J18: LOCOSC | K18: 45216 | L18: 2015 | M18: 451 | O18: ='EQUIPO ENERO 2025'!AP18 -> 0 | P18: =O18 -> 0 | Q18: =AK18 -> 0 | R18: =AL18 -> 0 | S18: =AM18 -> 0 | T18: =AN18 -> 0 | AJ18: ='EQUIPO ENERO 2025'!AP18 -> 0 | AK18: =P18-Z18+AE18+U18 -> 0 | AL18: =Q18-AA18+AF18+V18 -> 0 | AM18: =R18-AB18+AG18+W18 -> 0 | AN18: =S18-AC18+AH18+X18 -> 0 | AO18: =T18-AD18+AI18+Y18 -> 0 | AQ18: =AO18 -> 0
A19: =A18+1 -> 14 | B19: BALANZA DE LABORATORIO 1500g x 0.5g | C19: N/A | D19: ELECTRONIC BALANCE | E19: SE-WT15002KF | F19: 1 500 x 0.05 kg | G19: #VALUE! | H19: 2800 | I19: SE-WT15002KF-5 | J19: LOCOSC | K19: 45107 | L19: LP230224-1 | M19: 393 | O19: ='EQUIPO ENERO 2025'!AP19 -> 5 | P19: =O19 -> 5 | Q19: =AK19 -> 5 | R19: =AL19 -> 5 | S19: =AM19 -> 5 | T19: =AN19 -> 5 | AJ19: ='EQUIPO ENERO 2025'!AP19 -> 5 | AK19: =P19-Z19+AE19+U19 -> 5 | AL19: =Q19-AA19+AF19+V19 -> 5 | AM19: =R19-AB19+AG19+W19 -> 5 | AN19: =S19-AC19+AH19+X19 -> 5 | AO19: =T19-AD19+AI19+Y19 -> 5 | AQ19: =AO19 -> 5
A20: =A19+1 -> 15 | B20: BALANZA DE LABORATORIO CAPACIDAD 15 kg x 0.1g | C20: No. 1 | D20: ELECTRONIC BALANCE | E20: SE150001XD | F20: 15 kg x 0.1 g | G20: #VALUE! | H20: 9180 | I20: SE-WT150001XD | J20: LOCOSC | K20: 45316 | M20: 15 | O20: ='EQUIPO ENERO 2025'!AP20 -> 0 | P20: =O20 -> 0 | Q20: =AK20 -> 0 | R20: =AL20 -> 0 | S20: =AM20 -> 0 | T20: =AN20 -> 0 | AJ20: ='EQUIPO ENERO 2025'!AP20 -> 0 | AK20: =P20-Z20+AE20+U20 -> 0 | AL20: =Q20-AA20+AF20+V20 -> 0 | AM20: =R20-AB20+AG20+W20 -> 0 | AN20: =S20-AC20+AH20+X20 -> 0 | AO20: =T20-AD20+AI20+Y20 -> 0 | AQ20: =AO20 -> 0
A21: =A20+1 -> 16 | B21: BALANZA DE LABORATORIO CAPACIDAD 300 g x 1 mg | C21: N/A | D21: ELECTRONIC BALANCE | E21: SE-3003GH | F21: 300 g x 1 mg | G21: #VALUE! | H21: 36300 | I21: SE3003GH | J21: LOCOSC | K21: 45299 | M21: 6 | O21: ='EQUIPO ENERO 2025'!AP21 -> 0 | P21: =O21 -> 0 | Q21: =AK21 -> 0 | R21: =AL21 -> 0 | S21: =AM21 -> 0 | T21: =AN21 -> 0 | AJ21: ='EQUIPO ENERO 2025'!AP21 -> 0 | AK21: =P21-Z21+AE21+U21 -> 0 | AL21: =Q21-AA21+AF21+V21 -> 0 | AM21: =R21-AB21+AG21+W21 -> 0 | AN21: =S21-AC21+AH21+X21 -> 0 | AO21: =T21-AD21+AI21+Y21 -> 0 | AQ21: =AO21 -> 0
A22: =A21+1 -> 17 | B22: BALANZA ANALITICA CAPACIDAD DE 5 000g x 0.01 g | C22: N/A | D22: ELECTRONIC BALANCE | E22: SE-5 0002CF | F22: 5 000 x 0.01 g | G22: #VALUE! | I22: SE50002CF | J22: LOCOSC | K22: 45336 | L22: 669885E9 | M22: 37 | O22: ='EQUIPO ENERO 2025'!AP22 -> 0 | P22: =O22 -> 0 | Q22: =AK22 -> 0 | R22: =AL22 -> 0 | S22: =AM22 -> 0 | T22: =AN22 -> 0 | AJ22: ='EQUIPO ENERO 2025'!AP22 -> 0 | AK22: =P22-Z22+AE22+U22 -> 0 | AL22: =Q22-AA22+AF22+V22 -> 0 | AM22: =R22-AB22+AG22+W22 -> 0 | AN22: =S22-AC22+AH22+X22 -> 0 | AO22: =T22-AD22+AI22+Y22 -> 0 | AQ22: =AO22 -> 0
A23: =A22+1 -> 18 | B23: BALANZA ANALITICA CAPACIDAD DE 1 000 g x 20 mg | C23: N/A | D23: ELECTRONIC BALANCE | E23: SE-10003N | F23: 1 000 g x 20 mg | G23: #VALUE! | I23: SE10003N | J23: LOCOSC | K23: 45336 | L23: 669885E9 | M23: 37 | O23: ='EQUIPO ENERO 2025'!AP23 -> 0 | P23: =O23 -> 0 | Q23: =AK23 -> 0 | R23: =AL23 -> 0 | S23: =AM23 -> 0 | T23: =AN23 -> 0 | AJ23: ='EQUIPO ENERO 2025'!AP23 -> 0 | AK23: =P23-Z23+AE23+U23 -> 0 | AL23: =Q23-AA23+AF23+V23 -> 0 | AM23: =R23-AB23+AG23+W23 -> 0 | AN23: =S23-AC23+AH23+X23 -> 0 | AO23: =T23-AD23+AI23+Y23 -> 0 | AQ23: =AO23 -> 0
A24: =A23+1 -> 19 | B24: BALANZA ANALITICA CAPACIDAD DE 210 g x 10 mg | C24: N/A | D24: ELECTRONIC BALANCE | E24: SE-2085A | F24: 210 g x 10 mg | G24: #VALUE! | I24: SE2085A | J24: LOCOSC | K24: 45336 | L24: 669885E9 | M24: 38 | O24: ='EQUIPO ENERO 2025'!AP24 -> 0 | P24: =O24 -> 0 | Q24: =AK24 -> 0 | R24: =AL24 -> 0 | S24: =AM24 -> 0 | T24: =AN24 -> 0 | AJ24: ='EQUIPO ENERO 2025'!AP24 -> 0 | AK24: =P24-Z24+AE24+U24 -> 0 | AL24: =Q24-AA24+AF24+V24 -> 0 | AM24: =R24-AB24+AG24+W24 -> 0 | AN24: =S24-AC24+AH24+X24 -> 0 | AO24: =T24-AD24+AI24+Y24 -> 0 | AQ24: =AO24 -> 0
A25: =A24+1 -> 20 | B25: BALANZA DE LABORATORIO CAPACIDAD 420 x 0.001g LUNA | C25: No.1 | E25: SE-LPB423E | F25: 420 x 0.001 g | G25: #VALUE! | I25: LPB423E | J25: ADAM | K25: 45454 | L25: 34687-035292 | M25: 76 | O25: ='EQUIPO ENERO 2025'!AP25 -> 0 | P25: =O25 -> 0 | Q25: =AK25 -> 0 | R25: =AL25 -> 0 | S25: =AM25 -> 0 | T25: =AN25 -> 0 | AJ25: ='EQUIPO ENERO 2025'!AP25 -> 0 | AK25: =P25-Z25+AE25+U25 -> 0 | AL25: =Q25-AA25+AF25+V25 -> 0 | AM25: =R25-AB25+AG25+W25 -> 0 | AN25: =S25-AC25+AH25+X25 -> 0 | AO25: =T25-AD25+AI25+Y25 -> 0 | AQ25: =AO25 -> 0
A26: =A25+1 -> 21 | B26: BÁSCULA DE MESA | C26: No. 1 | D26: BRECKNELL | E26: SE-7680W | F26: 3 x 0.005 kg | G26: #VALUE! | H26: 2800 | I26: SE-LP7680-3Kg | J26: LOCOSC | K26: 45574 | L26: LP3211240 | M26: 71 | O26: ='EQUIPO ENERO 2025'!AP26 -> 8 | P26: =O26 -> 8 | Q26: =AK26 -> 8 | R26: =AL26 -> 8 | S26: =AM26 -> 8 | T26: =AN26 -> 8 | AJ26: ='EQUIPO ENERO 2025'!AP26 -> 8 | AK26: =P26-Z26+AE26+U26 -> 8 | AL26: =Q26-AA26+AF26+V26 -> 8 | AM26: =R26-AB26+AG26+W26 -> 8 | AN26: =S26-AC26+AH26+X26 -> 8 | AO26: =T26-AD26+AI26+Y26 -> 8 | AQ26: =AO26 -> 8
A27: =A26+1 -> 22 | B27: BÁSCULA DE MESA | C27: No. 1 | D27: BRECKNELL | E27: SE-7680W | F27: 6 x 0.001 kg | G27: #VALUE! | H27: 2800 | I27: SE-LP7680-6Kg | J27: LOCOSC | K27: 45574 | L27: LP3211240 | M27: 71 | O27: ='EQUIPO ENERO 2025'!AP27 -> 10 | P27: =O27 -> 10 | Q27: =AK27 -> 10 | R27: =AL27 -> 10 | S27: =AM27 -> 10 | T27: =AN27 -> 10 | AJ27: ='EQUIPO ENERO 2025'!AP27 -> 10 | AK27: =P27-Z27+AE27+U27 -> 10 | AL27: =Q27-AA27+AF27+V27 -> 10 | AM27: =R27-AB27+AG27+W27 -> 10 | AN27: =S27-AC27+AH27+X27 -> 10 | AO27: =T27-AD27+AI27+Y27 -> 10 | AQ27: =AO27 -> 10
A28: =A27+1 -> 23 | B28: BÁSCULA DE MESA | C28: No. 1 | D28: BRECKNELL | E28: SE-7680W | F28: 15 x 0.002 kg | G28: #VALUE! | H28: 2800 | I28: SE-LP7680-15Kg | J28: LOCOSC | K28: 45574 | L28: LP3211240 | M28: 71 | O28: ='EQUIPO ENERO 2025'!AP28 -> 6 | P28: =O28 -> 6 | Q28: =AK28 -> 6 | R28: =AL28 -> 6 | S28: =AM28 -> 6 | T28: =AN28 -> 6 | AJ28: ='EQUIPO ENERO 2025'!AP28 -> 6 | AK28: =P28-Z28+AE28+U28 -> 6 | AL28: =Q28-AA28+AF28+V28 -> 6 | AM28: =R28-AB28+AG28+W28 -> 6 | AN28: =S28-AC28+AH28+X28 -> 6 | AO28: =T28-AD28+AI28+Y28 -> 6 | AQ28: =AO28 -> 6 | AS28: 337/PAPYS
A29: =A28+1 -> 24 | B29: BASCULA DE MESA MODELO SE-7680W | C29: No. 1 | D29: BRECKNELL | E29: SE-7680W | F29: 30 x 0.005 kg | G29: #VALUE! | H29: 3000 | I29: SE-LP7680-30kg | J29: LOCOSC | K29: 45107 | L29: LP230224-1 | M29: 390 | O29: ='EQUIPO ENERO 2025'!AP29 -> 5 | P29: =O29 -> 5 | Q29: =AK29 -> 5 | R29: =AL29 -> 5 | S29: =AM29 -> 5 | T29: =AN29 -> 5 | AJ29: ='EQUIPO ENERO 2025'!AP29 -> 5 | AK29: =P29-Z29+AE29+U29 -> 5 | AL29: =Q29-AA29+AF29+V29 -> 5 | AM29: =R29-AB29+AG29+W29 -> 5 | AN29: =S29-AC29+AH29+X29 -> 5 | AO29: =T29-AD29+AI29+Y29 -> 5 | AQ29: =AO29 -> 5
A30: =A29+1 -> 25 | B30: BALANZA ELECTRONIC BALANCE MODELO SE-2003CH DE 2000gx1mg | C30: N/A | D30: ELECTRONIC BALANCE | E30: SE-2003CH | F30: 200 x 1 mg | G30: #VALUE! | H30: 6300 | I30: SE-2003CH | J30: LOCOSC | K30: 45139 | L30: 781781092133 | M30: 419 | O30: ='EQUIPO ENERO 2025'!AP30 -> 0 | P30: =O30 -> 0 | Q30: =AK30 -> 0 | R30: =AL30 -> 0 | S30: =AM30 -> 0 | T30: =AN30 -> 0 | AJ30: ='EQUIPO ENERO 2025'!AP30 -> 0 | AK30: =P30-Z30+AE30+U30 -> 0 | AL30: =Q30-AA30+AF30+V30 -> 0 | AM30: =R30-AB30+AG30+W30 -> 0 | AN30: =S30-AC30+AH30+X30 -> 0 | AO30: =T30-AD30+AI30+Y30 -> 0 | AQ30: =AO30 -> 0
A31: =A30+1 -> 26 | B31: BASES DE CELDA DE CARGA PARA CELDAS DE ACEROS DE GUATEMALA | C31: NO. 2 | D31: S/M | E31: S/M | G31: #VALUE! | K31: 45568 | M31: 62 | O31: ='EQUIPO ENERO 2025'!AP31 -> 2 | P31: =O31 -> 2 | Q31: =AK31 -> 2 | R31: =AL31 -> 2 | S31: =AM31 -> 2 | T31: =AN31 -> 2 | AJ31: ='EQUIPO ENERO 2025'!AP31 -> 2 | AK31: =P31-Z31+AE31+U31 -> 2 | AL31: =Q31-AA31+AF31+V31 -> 2 | AM31: =R31-AB31+AG31+W31 -> 2 | AN31: =S31-AC31+AH31+X31 -> 2 | AO31: =T31-AD31+AI31+Y31 -> 2 | AQ31: =AO31 -> 2
A32: =A31+1 -> 27 | B32: BASCULA COLGANTE CAPACIDAD 5 t LP7650G | C32: NO.2 | D32: BRECKNELL | E32: SE-7650 | F32: 5 T | G32: #VALUE! | H32: 9500 | I32: SE-LP7650G-5T | J32: SIZEN | K32: 45666 | L32: LK24112701 | M32: 117 | O32: ='EQUIPO ENERO 2025'!AP32 -> 1 | P32: =O32 -> 1 | Q32: =AK32 -> 1 | R32: =AL32 -> 1 | S32: =AM32 -> 1 | T32: =AN32 -> 1 | AJ32: ='EQUIPO ENERO 2025'!AP32 -> 1 | AK32: =P32-Z32+AE32+U32 -> 1 | AL32: =Q32-AA32+AF32+V32 -> 1 | AM32: =R32-AB32+AG32+W32 -> 1 | AN32: =S32-AC32+AH32+X32 -> 1 | AO32: =T32-AD32+AI32+Y32 -> 1 | AQ32: =AO32 -> 1
A33: =A32+1 -> 28 | B33: BASCULA COLGANTE CAPACIDAD 10 t LP7650G | C33: No. 2 | D33: BRECKNELL | E33: SE-7650 | F33: 10 t | G33: #VALUE! | H33: Q16,800.00 Consultar primero | I33: SE-LP7650G-10T | J33: LOCOSC | K33: 45107 | L33: LP230224-1 | M33: 393 | O33: ='EQUIPO ENERO 2025'!AP33 -> 1 | P33: =O33 -> 1 | Q33: =AK33 -> 1 | R33: =AL33 -> 1 | S33: =AM33 -> 1 | T33: =AN33 -> 1 | AJ33: ='EQUIPO ENERO 2025'!AP33 -> 1 | AK33: =P33-Z33+AE33+U33 -> 1 | AL33: =Q33-AA33+AF33+V33 -> 1 | AM33: =R33-AB33+AG33+W33 -> 1 | AN33: =S33-AC33+AH33+X33 -> 1 | AO33: =T33-AD33+AI33+Y33 -> 1 | AQ33: =AO33 -> 1
A34: =A33+1 -> 29 | B34: BASCULA COLGANTE CAPACIDAD 300kg LP7652G | C34: No. 1 | D34: BRECKNELL | E34: SE-7652 | F34: 300 x 0.1 kg | G34: #VALUE! | H34: 650 | I34: SE-COLG-LP7652G | J34: LOCOSC | K34: 45107 | L34: LP230224-1 | M34: 389 | O34: ='EQUIPO ENERO 2025'!AP34 -> 11 | P34: =O34 -> 11 | Q34: =AK34 -> 11 | R34: =AL34 -> 11 | S34: =AM34 -> 11 | T34: =AN34 -> 11 | AJ34: ='EQUIPO ENERO 2025'!AP34 -> 11 | AK34: =P34-Z34+AE34+U34 -> 11 | AL34: =Q34-AA34+AF34+V34 -> 11 | AM34: =R34-AB34+AG34+W34 -> 11 | AN34: =S34-AC34+AH34+X34 -> 11 | AO34: =T34-AD34+AI34+Y34 -> 11 | AQ34: =AO34 -> 11
A35: =A34+1 -> 30 | B35: BASCULA COLGANTE PANTALLA LED DE 5 DIGITOS | C35: No. 1 | D35: BRECKNELL | E35: SE-7561 | F35: 300 x 0.1 kg | G35: #VALUE! | H35: 1800 | I35: SE-LP7561E | J35: LOCOSC | K35: 44592 | O35: ='EQUIPO ENERO 2025'!AP35 -> 6 | P35: =O35 -> 6 | Q35: =AK35 -> 6 | R35: =AL35 -> 6 | S35: =AM35 -> 6 | T35: =AN35 -> 6 | AJ35: ='EQUIPO ENERO 2025'!AP35 -> 6 | AK35: =P35-Z35+AE35+U35 -> 6 | AL35: =Q35-AA35+AF35+V35 -> 6 | AM35: =R35-AB35+AG35+W35 -> 6 | AN35: =S35-AC35+AH35+X35 -> 6 | AO35: =T35-AD35+AI35+Y35 -> 6 | AQ35: =AO35 -> 6
A36: =A35+1 -> 31 | B36: BASCULA DE MESA CAPACIDAD 30kgx1g | C36: No. 1 | D36: ELECTRONIC BALANCE | E36: SE-WT300001X | F36: 30 kg x 1 g | G36: #VALUE! | H36: 3400 | I36: SE-WT300001X | J36: LOCOSC | K36: 45107 | L36: LP230224-1 | M36: 393 | O36: ='EQUIPO ENERO 2025'!AP36 -> 4 | P36: =O36 -> 4 | Q36: =AK36 -> 4 | R36: =AL36 -> 4 | S36: =AM36 -> 4 | T36: =AN36 -> 4 | AJ36: ='EQUIPO ENERO 2025'!AP36 -> 4 | AK36: =P36-Z36+AE36+U36 -> 4 | AL36: =Q36-AA36+AF36+V36 -> 4 | AM36: =R36-AB36+AG36+W36 -> 4 | AN36: =S36-AC36+AH36+X36 -> 4 | AO36: =T36-AD36+AI36+Y36 -> 4 | AQ36: =AO36 -> 4
A37: =A36+1 -> 32 | B37: BASCULA DE MESA MODELO SE-Y2-208 CAPACIDAD 40kg X 5g | C37: No. 1 | D37: TECNO SCALE | E37: SE-Y2-208 | F37: 40 kg x 5 g | G37: #VALUE! | H37: 550 | I37: SE-Y2-208 | J37: LOCOSC | K37: 45328 | L37: LP230224-1 | M37: 32 | N37: AUTORIZADO POR WILLIAM SÁNCHEZ | O37: ='EQUIPO ENERO 2025'!AP37 -> 14 | P37: =O37 -> 14 | Q37: =AK37 -> 12 | R37: =AL37 -> 12 | S37: =AM37 -> 12 | T37: =AN37 -> 12 | Z37: 2 | AJ37: ='EQUIPO ENERO 2025'!AP37 -> 14 | AK37: =P37-Z37+AE37+U37 -> 12 | AL37: =Q37-AA37+AF37+V37 -> 12 | AM37: =R37-AB37+AG37+W37 -> 12 | AN37: =S37-AC37+AH37+X37 -> 12 | AO37: =T37-AD37+AI37+Y37 -> 12 | AQ37: =AO37 -> 12 | AR37: NO TIENE FUE CORTESIA | AS37: 319/ 320/COPASA
A38: =A37+1 -> 33 | B38: BASCULA DE PISO ACERO INOXIDABLE CAPACIDAD 150kg DE 40X50 | C38: No. 1 | D38: BRECKNELL | E38: SE-7610W | F38: 150 x 0.02 kg | G38: #VALUE! | H38: 7500 | I38: SE-7510W-150kg | J38: LOCOSC | K38: 45107 | L38: LP230224-1 | M38: 392 | N38: ACEROS | O38: ='EQUIPO ENERO 2025'!AP38 -> 5 | P38: =O38 -> 5 | Q38: =AK38 -> 5 | R38: =AL38 -> 5 | S38: =AM38 -> 5 | T38: =AN38 -> 5 | AA38: 1 | AF38: 1 | AJ38: ='EQUIPO ENERO 2025'!AP38 -> 5 | AK38: =P38-Z38+AE38+U38 -> 5 | AL38: =Q38-AA38+AF38+V38 -> 5 | AM38: =R38-AB38+AG38+W38 -> 5 | AN38: =S38-AC38+AH38+X38 -> 5 | AO38: =T38-AD38+AI38+Y38 -> 5 | AP38: 1 | AQ38: =AO38 -> 5 | AS38: 330
A39: =A38+1 -> 34 | B39: BÁSCULA DE PISO SS ACERO INOXIDABLE CAPACIDAD 150 kg DE 60 x 60 cm | C39: NO. 1 | D39: BRECKNELL | E39: SE-7610WSS | F39: 150 x 0.02 kg | G39: #VALUE! | H39: 10800 | I39: SE7610W-SS-6060-150kg | J39: LOCOSC | K39: 45673 | L39: 240907-1 | M39: 126 | O39: ='EQUIPO ENERO 2025'!AP39 -> 5 | P39: =O39 -> 5 | Q39: =AK39 -> 5 | R39: =AL39 -> 5 | S39: =AM39 -> 5 | T39: =AN39 -> 5 | AJ39: ='EQUIPO ENERO 2025'!AP39 -> 5 | AK39: =P39-Z39+AE39+U39 -> 5 | AL39: =Q39-AA39+AF39+V39 -> 5 | AM39: =R39-AB39+AG39+W39 -> 5 | AN39: =S39-AC39+AH39+X39 -> 5 | AO39: =T39-AD39+AI39+Y39 -> 5 | AP39: 1 | AQ39: =AO39 -> 5
A40: =A39+1 -> 35 | B40: BASCULA DE PISO CAPACIDAD 30kg DE 40X40 | C40: No. 1 | D40: BRECKNELL | E40: SE-7610 | F40: 30 x 0.005 kg | G40: #VALUE! | H40: 2800 | I40: SE-LP7610-30kg | J40: LOCOSC | K40: 45574 | L40: LP3211240 | M40: 71 | O40: ='EQUIPO ENERO 2025'!AP40 -> 8 | P40: =O40 -> 8 | Q40: =AK40 -> 8 | R40: =AL40 -> 8 | S40: =AM40 -> 8 | T40: =AN40 -> 8 | AJ40: ='EQUIPO ENERO 2025'!AP40 -> 8 | AK40: =P40-Z40+AE40+U40 -> 8 | AL40: =Q40-AA40+AF40+V40 -> 8 | AM40: =R40-AB40+AG40+W40 -> 8 | AN40: =S40-AC40+AH40+X40 -> 8 | AO40: =T40-AD40+AI40+Y40 -> 8 | AP40: 1 | AQ40: =AO40 -> 8
A41: =A40+1 -> 36 | B41: BASCULA DE PISO CAPACIDAD 60kg DE 40X50 | C41: No. 1 | D41: BRECKNELL | E41: SE-7610 | F41: 60 x 0.01 kg | G41: #VALUE! | H41: 2800 | I41: SE-LP7610-60kg | J41: LOCOSC | K41: 45574 | L41: LP3211240 | M41: 71 | O41: ='EQUIPO ENERO 2025'!AP41 -> 2 | P41: =O41 -> 2 | Q41: =AK41 -> 2 | R41: =AL41 -> 2 | S41: =AM41 -> 2 | T41: =AN41 -> 2 | AJ41: ='EQUIPO ENERO 2025'!AP41 -> 2 | AK41: =P41-Z41+AE41+U41 -> 2 | AL41: =Q41-AA41+AF41+V41 -> 2 | AM41: =R41-AB41+AG41+W41 -> 2 | AN41: =S41-AC41+AH41+X41 -> 2 | AO41: =T41-AD41+AI41+Y41 -> 2 | AP41: 0 | AQ41: =AO41 -> 2
...

Sheet EQUIPO MARZO 2025  1
B1: SOLUCIONES EXACTAS, S.A. | AR1: Codigo: FO-SE-053 | AV1: Codigo: FO-SE-053
B3: LISTADO INVENTARIO BODEGAS FEBRERO | AI3: MAR | AK3: MARZO | AR3: Versión: 02 | AV3: Versión: 02
A4: No. | B4: PRODUCTO | C4: No. BODEGA | D4: MARCA | E4: MODELO | F4: CAPACIDAD | G4: IMAGEN | H4: PRECIO | I4: CODIGO INTERNO | J4: PROVEEDOR | K4: FECHA INGRESO BODEGA | L4: FACTURA No. PROVEEDOR | M4: BOLETA INGRESO BODEGA | N4: OBSERVACION | O4: VIENE MES ANTERIOR | P4: EXISTENCIA INICIO SEMANA | U4: INGRESO POR IMPORTACION O COMPRA | Z4: DESCARGA Y/O SALIDA | AE4: DEVOLUCIONES | AJ4: INICIO DE MES | AK4: EXISTENCIA POR SEMANA | AP4: DEMO | AQ4: TOTAL EXISTENCIA MENSUAL | AR4: FACTURA VENTA | AS4: BOLETA DE SALIDA | AT4: ENVIO | AU4: FIRMA ULTIMO INVENTARIO | AV4: FECHA ULTIMA REVISION
P5: 1 | Q5: 2 | R5: 3 | S5: 4 | T5: 5 | U5: 1 | V5: 2 | W5: 3 | X5: 4 | Y5: 5 | Z5: 1 | AA5: 2 | AB5: 3 | AC5: 4 | AD5: 5 | AE5: 1 | AF5: 2 | AG5: 3 | AH5: 4 | AI5: 5 | AK5: 1 | AL5: 2 | AM5: 3 | AN5: 4 | AO5: 5
A6: 1 | B6: ADAPTADOR PARA INDICADOR 9V1.2A MODELO: KEERDA | C6: No. 2 | D6: KEERDA | E6: DZ012ELL090120U | F6: 9V | G6: #VALUE! | H6: 395 | I6: SE-ADAT9V | J6: SIZEIN | K6: 45666 | L6: LK24112701 | M6: 118 | O6: ='EQUIPO FEBRERO 2025 1'!AQ6 -> 43 | P6: =O6 -> 43 | Q6: =AK6 -> 43 | R6: =AL6 -> 43 | S6: =AM6 -> 43 | T6: =AN6 -> 43 | Z6: 2 | AE6: 2 | AJ6: ='EQUIPO ENERO 2025'!AP6 -> 47 | AK6: =P6-Z6+AE6+U6 -> 43 | AL6: =Q6-AA6+AF6+V6 -> 43 | AM6: =R6-AB6+AG6+W6 -> 43 | AN6: =S6-AC6+AH6+X6 -> 43 | AO6: =T6-AD6+AI6+Y6 -> 43 | AQ6: =AO6 -> 43 | AS6: 363
A7: =A6+1 -> 2 | B7: ADAPTADOR GENERICO 9V 600 mA | C7: No.2 | D7: Byp | F7: 9v | K7: 45712 | M7: 162 | O7: ='EQUIPO FEBRERO 2025 1'!AQ7 -> 10 | P7: =O7 -> 10 | Q7: =AK7 -> 9 | R7: =AL7 -> 9 | S7: =AM7 -> 9 | T7: =AN7 -> 9 | Z7: 1 | AK7: =P7-Z7+AE7+U7 -> 9 | AL7: =Q7-AA7+AF7+V7 -> 9 | AM7: =R7-AB7+AG7+W7 -> 9 | AN7: =S7-AC7+AH7+X7 -> 9 | AO7: =T7-AD7+AI7+Y7 -> 9 | AQ7: =AO7 -> 9 | AS7: 351
A8: =A7+1 -> 3 | B8: ADAPTADORES GENERICOS 5 V 1 AMP AC/DC | C8: No. 2 | D8: BRECKNELL | E8: S/M | G8: #VALUE! | I8: SE-ADAP-1 AMP | J8: BRECKNELL | K8: 44592 | O8: ='EQUIPO FEBRERO 2025 1'!AQ8 -> 2 | P8: =O8 -> 2 | Q8: =AK8 -> 2 | R8: =AL8 -> 2 | S8: =AM8 -> 2 | T8: =AN8 -> 2 | AJ8: ='EQUIPO ENERO 2025'!AP8 -> 2 | AK8: =P8-Z8+AE8+U8 -> 2 | AL8: =Q8-AA8+AF8+V8 -> 2 | AM8: =R8-AB8+AG8+W8 -> 2 | AN8: =S8-AC8+AH8+X8 -> 2 | AO8: =T8-AD8+AI8+Y8 -> 2 | AQ8: =AO8 -> 2
A9: =A8+1 -> 4 | B9: ADAPTADORES SBI 505 ORIGINAL AWT05-505896 | C9: No. 2 | D9: AVERY WEIGH TRONIX | E9: AWT05-505896 | G9: #VALUE! | H9: 550 | I9: SE-ADAP-SBI505 | J9: AVERY WEIGH TRONIX | K9: 44592 | O9: ='EQUIPO FEBRERO 2025 1'!AQ9 -> 8 | P9: =O9 -> 8 | Q9: =AK9 -> 8 | R9: =AL9 -> 8 | S9: =AM9 -> 8 | T9: =AN9 -> 8 | AJ9: ='EQUIPO ENERO 2025'!AP9 -> 8 | AK9: =P9-Z9+AE9+U9 -> 8 | AL9: =Q9-AA9+AF9+V9 -> 8 | AM9: =R9-AB9+AG9+W9 -> 8 | AN9: =S9-AC9+AH9+X9 -> 8 | AO9: =T9-AD9+AI9+Y9 -> 8 | AQ9: =AO9 -> 8
A10: =A9+1 -> 5 | B10: ADAPTADOR BI 12T | C10: No. 2 | D10: BRECKNELL | E10: BI 12T | F10: 12t | G10: #VALUE! | I10: SE-ADAP-BI-12T | J10: BRECKNELL | K10: 44592 | O10: ='EQUIPO FEBRERO 2025 1'!AQ10 -> 1 | P10: =O10 -> 1 | Q10: =AK10 -> 1 | R10: =AL10 -> 1 | S10: =AM10 -> 1 | T10: =AN10 -> 1 | AJ10: ='EQUIPO ENERO 2025'!AP10 -> 1 | AK10: =P10-Z10+AE10+U10 -> 1 | AL10: =Q10-AA10+AF10+V10 -> 1 | AM10: =R10-AB10+AG10+W10 -> 1 | AN10: =S10-AC10+AH10+X10 -> 1 | AO10: =T10-AD10+AI10+Y10 -> 1 | AQ10: =AO10 -> 1
A11: =A10+1 -> 6 | B11: ADAPTADOR DE MODULOS INALAMBRICOS SE-7660 | C11: No.2 | E11: SE-ADAPT-7660 | G11: #VALUE! | J11: LOCOSC | K11: 45464 | M11: 87 | O11: ='EQUIPO FEBRERO 2025 1'!AQ11 -> 2 | P11: =O11 -> 2 | Q11: =AK11 -> 2 | R11: =AL11 -> 2 | S11: =AM11 -> 2 | T11: =AN11 -> 2 | AJ11: ='EQUIPO ENERO 2025'!AP11 -> 2 | AK11: =P11-Z11+AE11+U11 -> 2 | AL11: =Q11-AA11+AF11+V11 -> 2 | AM11: =R11-AB11+AG11+W11 -> 2 | AN11: =S11-AC11+AH11+X11 -> 2 | AO11: =T11-AD11+AI11+Y11 -> 2 | AQ11: =AO11 -> 2
A12: =A11+1 -> 7 | B12: ADAPTADOR DE CORRIENTE DE INDICADOR SE7517/ REPARADO DE CABLE | C12: NO.2 | D12: KEERDA | E12: DZ007AHL050100U | F12: 5.0V/1.0Ah | I12: SE-DZ007 | J12: LOCOSC | M12: 113 | O12: ='EQUIPO FEBRERO 2025 1'!AQ12 -> 1 | P12: =O12 -> 1 | Q12: =AK12 -> 1 | R12: =AL12 -> 1 | S12: =AM12 -> 1 | T12: =AN12 -> 1 | AJ12: ='EQUIPO ENERO 2025'!AP12 -> 1 | AK12: =P12-Z12+AE12+U12 -> 1 | AL12: =Q12-AA12+AF12+V12 -> 1 | AM12: =R12-AB12+AG12+W12 -> 1 | AN12: =S12-AC12+AH12+X12 -> 1 | AO12: =T12-AD12+AI12+Y12 -> 1 | AQ12: =AO12 -> 1
A13: =A12+1 -> 8 | B13: ADAPTADORES DE CORRIENTE PARA MODULOS INALAMBRICOS SE-7519A | C13: NO.2 | D13: S/M | E13: ZF120A-0421000 | F13: 4.2V/10A | G13: #VALUE! | I13: SE-ADAP-A | J13: LOCOSC | K13: 45582 | M13: 81 | O13: ='EQUIPO FEBRERO 2025 1'!AQ13 -> 2 | P13: =O13 -> 2 | Q13: =AK13 -> 2 | R13: =AL13 -> 2 | S13: =AM13 -> 2 | T13: =AN13 -> 2 | AJ13: ='EQUIPO ENERO 2025'!AP13 -> 2 | AK13: =P13-Z13+AE13+U13 -> 2 | AL13: =Q13-AA13+AF13+V13 -> 2 | AM13: =R13-AB13+AG13+W13 -> 2 | AN13: =S13-AC13+AH13+X13 -> 2 | AO13: =T13-AD13+AI13+Y13 -> 2 | AQ13: =AO13 -> 2
A14: =A13+1 -> 9 | B14: ARMARIOS ELECTRICOS ST4-420 | C14: No. 2 | D14: BRECKNELL | E14: ST4-420 | G14: #VALUE! | I14: SE-ARMAELEC | J14: BRECKNELL | K14: 44592 | O14: ='EQUIPO FEBRERO 2025 1'!AQ14 -> 3 | P14: =O14 -> 3 | Q14: =AK14 -> 3 | R14: =AL14 -> 3 | S14: =AM14 -> 3 | T14: =AN14 -> 3 | AJ14: ='EQUIPO ENERO 2025'!AP14 -> 3 | AK14: =P14-Z14+AE14+U14 -> 3 | AL14: =Q14-AA14+AF14+V14 -> 3 | AM14: =R14-AB14+AG14+W14 -> 3 | AN14: =S14-AC14+AH14+X14 -> 3 | AO14: =T14-AD14+AI14+Y14 -> 3 | AQ14: =AO14 -> 3
A15: =A14+1 -> 10 | B15: ARGOLLAS PARA BÁSCULAS PESA EJES | C15: NO.2 | D15: S/M | E15: M-20 | F15: S/C | G15: #VALUE! | I15: SE-ARG-PPEJES | J15: LOCOSC | K15: 45673 | L15: 240907-1 | M15: 131 | O15: ='EQUIPO FEBRERO 2025 1'!AQ15 -> 0 | P15: =O15 -> 0 | Q15: =AK15 -> 0 | R15: =AL15 -> 0 | S15: =AM15 -> 0 | T15: =AN15 -> 0 | AJ15: ='EQUIPO ENERO 2025'!AP15 -> 0 | AK15: =P15-Z15+AE15+U15 -> 0 | AL15: =Q15-AA15+AF15+V15 -> 0 | AM15: =R15-AB15+AG15+W15 -> 0 | AN15: =S15-AC15+AH15+X15 -> 0 | AO15: =T15-AD15+AI15+Y15 -> 0 | AQ15: =AO15 -> 0
A16: =A15+1 -> 11 | B16: BALANZA DE BOLSILLO CAPACIDAD DE 200x0.01g | C16: No. 1 | E16: HY-YH-J100120 | F16: 2 000 x 0.01 g | G16: #VALUE! | H16: 150 | I16: SE-FAB-GUA | K16: 44592 | O16: ='EQUIPO FEBRERO 2025 1'!AQ16 -> 5 | P16: =O16 -> 5 | Q16: =AK16 -> 5 | R16: =AL16 -> 5 | S16: =AM16 -> 5 | T16: =AN16 -> 5 | AJ16: ='EQUIPO ENERO 2025'!AP16 -> 5 | AK16: =P16-Z16+AE16+U16 -> 5 | AL16: =Q16-AA16+AF16+V16 -> 5 | AM16: =R16-AB16+AG16+W16 -> 5 | AN16: =S16-AC16+AH16+X16 -> 5 | AO16: =T16-AD16+AI16+Y16 -> 5 | AQ16: =AO16 -> 5
A17: =A16+1 -> 12 | B17: BALANZA DE LABORATORIO 1 000 x0.01g | C17: N/A | D17: ELECTRONIC BALANCE | E17: SE10002K | F17: 1 000 x 0.01 g | G17: #VALUE! | H17: 9180 | I17: SE-WTB1002K | J17: LOCOSC | K17: 45316 | M17: 15 | O17: ='EQUIPO FEBRERO 2025 1'!AQ17 -> 0 | P17: =O17 -> 0 | Q17: =AK17 -> 0 | R17: =AL17 -> 0 | S17: =AM17 -> 0 | T17: =AN17 -> 0 | AJ17: ='EQUIPO ENERO 2025'!AP17 -> 0 | AK17: =P17-Z17+AE17+U17 -> 0 | AL17: =Q17-AA17+AF17+V17 -> 0 | AM17: =R17-AB17+AG17+W17 -> 0 | AN17: =S17-AC17+AH17+X17 -> 0 | AO17: =T17-AD17+AI17+Y17 -> 0 | AQ17: =AO17 -> 0
A18: =A17+1 -> 13 | B18: BALANZA DE LABORATORIO 10000x0.1g | C18: No. 1 | D18: ELECTRONIC BALANCE | E18: SE-WT100001X | F18: 1 000 x 0.1 g | G18: #VALUE! | H18: 4600 | I18: SE-WT100001X | J18: LOCOSC | K18: 45216 | L18: 2015 | M18: 451 | O18: ='EQUIPO FEBRERO 2025 1'!AQ18 -> 0 | P18: =O18 -> 0 | Q18: =AK18 -> 0 | R18: =AL18 -> 0 | S18: =AM18 -> 0 | T18: =AN18 -> 0 | AJ18: ='EQUIPO ENERO 2025'!AP18 -> 0 | AK18: =P18-Z18+AE18+U18 -> 0 | AL18: =Q18-AA18+AF18+V18 -> 0 | AM18: =R18-AB18+AG18+W18 -> 0 | AN18: =S18-AC18+AH18+X18 -> 0 | AO18: =T18-AD18+AI18+Y18 -> 0 | AQ18: =AO18 -> 0
A19: =A18+1 -> 14 | B19: BALANZA DE LABORATORIO 1500g x 0.5g | C19: N/A | D19: ELECTRONIC BALANCE | E19: SE-WT15002KF | F19: 1 500 x 0.05 kg | G19: #VALUE! | H19: 2800 | I19: SE-WT15002KF-5 | J19: LOCOSC | K19: 45107 | L19: LP230224-1 | M19: 393 | O19: ='EQUIPO FEBRERO 2025 1'!AQ19 -> 5 | P19: =O19 -> 5 | Q19: =AK19 -> 5 | R19: =AL19 -> 5 | S19: =AM19 -> 5 | T19: =AN19 -> 5 | AJ19: ='EQUIPO ENERO 2025'!AP19 -> 5 | AK19: =P19-Z19+AE19+U19 -> 5 | AL19: =Q19-AA19+AF19+V19 -> 5 | AM19: =R19-AB19+AG19+W19 -> 5 | AN19: =S19-AC19+AH19+X19 -> 5 | AO19: =T19-AD19+AI19+Y19 -> 5 | AQ19: =AO19 -> 5
A20: =A19+1 -> 15 | B20: BALANZA DE LABORATORIO CAPACIDAD 15 kg x 0.1g | C20: No. 1 | D20: ELECTRONIC BALANCE | E20: SE150001XD | F20: 15 kg x 0.1 g | G20: #VALUE! | H20: 9180 | I20: SE-WT150001XD | J20: LOCOSC | K20: 45316 | M20: 15 | O20: ='EQUIPO FEBRERO 2025 1'!AQ20 -> 0 | P20: =O20 -> 0 | Q20: =AK20 -> 0 | R20: =AL20 -> 0 | S20: =AM20 -> 0 | T20: =AN20 -> 0 | AJ20: ='EQUIPO ENERO 2025'!AP20 -> 0 | AK20: =P20-Z20+AE20+U20 -> 0 | AL20: =Q20-AA20+AF20+V20 -> 0 | AM20: =R20-AB20+AG20+W20 -> 0 | AN20: =S20-AC20+AH20+X20 -> 0 | AO20: =T20-AD20+AI20+Y20 -> 0 | AQ20: =AO20 -> 0
A21: =A20+1 -> 16 | B21: BALANZA DE LABORATORIO CAPACIDAD 300 g x 1 mg | C21: N/A | D21: ELECTRONIC BALANCE | E21: SE-3003GH | F21: 300 g x 1 mg | G21: #VALUE! | H21: 36300 | I21: SE3003GH | J21: LOCOSC | K21: 45299 | M21: 6 | O21: ='EQUIPO FEBRERO 2025 1'!AQ21 -> 0 | P21: =O21 -> 0 | Q21: =AK21 -> 0 | R21: =AL21 -> 0 | S21: =AM21 -> 0 | T21: =AN21 -> 0 | AJ21: ='EQUIPO ENERO 2025'!AP21 -> 0 | AK21: =P21-Z21+AE21+U21 -> 0 | AL21: =Q21-AA21+AF21+V21 -> 0 | AM21: =R21-AB21+AG21+W21 -> 0 | AN21: =S21-AC21+AH21+X21 -> 0 | AO21: =T21-AD21+AI21+Y21 -> 0 | AQ21: =AO21 -> 0
A22: =A21+1 -> 17 | B22: BALANZA ANALITICA CAPACIDAD DE 5 000g x 0.01 g | C22: N/A | D22: ELECTRONIC BALANCE | E22: SE-5 0002CF | F22: 5 000 x 0.01 g | G22: #VALUE! | I22: SE50002CF | J22: LOCOSC | K22: 45336 | L22: 669885E9 | M22: 37 | O22: ='EQUIPO FEBRERO 2025 1'!AQ22 -> 0 | P22: =O22 -> 0 | Q22: =AK22 -> 0 | R22: =AL22 -> 0 | S22: =AM22 -> 0 | T22: =AN22 -> 0 | AJ22: ='EQUIPO ENERO 2025'!AP22 -> 0 | AK22: =P22-Z22+AE22+U22 -> 0 | AL22: =Q22-AA22+AF22+V22 -> 0 | AM22: =R22-AB22+AG22+W22 -> 0 | AN22: =S22-AC22+AH22+X22 -> 0 | AO22: =T22-AD22+AI22+Y22 -> 0 | AQ22: =AO22 -> 0
A23: =A22+1 -> 18 | B23: BALANZA ANALITICA CAPACIDAD DE 1 000 g x 20 mg | C23: N/A | D23: ELECTRONIC BALANCE | E23: SE-10003N | F23: 1 000 g x 20 mg | G23: #VALUE! | I23: SE10003N | J23: LOCOSC | K23: 45336 | L23: 669885E9 | M23: 37 | O23: ='EQUIPO FEBRERO 2025 1'!AQ23 -> 0 | P23: =O23 -> 0 | Q23: =AK23 -> 0 | R23: =AL23 -> 0 | S23: =AM23 -> 0 | T23: =AN23 -> 0 | AJ23: ='EQUIPO ENERO 2025'!AP23 -> 0 | AK23: =P23-Z23+AE23+U23 -> 0 | AL23: =Q23-AA23+AF23+V23 -> 0 | AM23: =R23-AB23+AG23+W23 -> 0 | AN23: =S23-AC23+AH23+X23 -> 0 | AO23: =T23-AD23+AI23+Y23 -> 0 | AQ23: =AO23 -> 0
A24: =A23+1 -> 19 | B24: BALANZA ANALITICA CAPACIDAD DE 210 g x 10 mg | C24: N/A | D24: ELECTRONIC BALANCE | E24: SE-2085A | F24: 210 g x 10 mg | G24: #VALUE! | I24: SE2085A | J24: LOCOSC | K24: 45336 | L24: 669885E9 | M24: 38 | O24: ='EQUIPO FEBRERO 2025 1'!AQ24 -> 0 | P24: =O24 -> 0 | Q24: =AK24 -> 0 | R24: =AL24 -> 0 | S24: =AM24 -> 0 | T24: =AN24 -> 0 | AJ24: ='EQUIPO ENERO 2025'!AP24 -> 0 | AK24: =P24-Z24+AE24+U24 -> 0 | AL24: =Q24-AA24+AF24+V24 -> 0 | AM24: =R24-AB24+AG24+W24 -> 0 | AN24: =S24-AC24+AH24+X24 -> 0 | AO24: =T24-AD24+AI24+Y24 -> 0 | AQ24: =AO24 -> 0
A25: =A24+1 -> 20 | B25: BALANZA DE LABORATORIO CAPACIDAD 420 x 0.001g LUNA | C25: No.1 | E25: SE-LPB423E | F25: 420 x 0.001 g | G25: #VALUE! | I25: LPB423E | J25: ADAM | K25: 45454 | L25: 34687-035292 | M25: 76 | O25: ='EQUIPO FEBRERO 2025 1'!AQ25 -> 0 | P25: =O25 -> 0 | Q25: =AK25 -> 0 | R25: =AL25 -> 0 | S25: =AM25 -> 0 | T25: =AN25 -> 0 | AJ25: ='EQUIPO ENERO 2025'!AP25 -> 0 | AK25: =P25-Z25+AE25+U25 -> 0 | AL25: =Q25-AA25+AF25+V25 -> 0 | AM25: =R25-AB25+AG25+W25 -> 0 | AN25: =S25-AC25+AH25+X25 -> 0 | AO25: =T25-AD25+AI25+Y25 -> 0 | AQ25: =AO25 -> 0
A26: =A25+1 -> 21 | B26: BÁSCULA DE MESA | C26: No. 1 | D26: BRECKNELL | E26: SE-7680W | F26: 3 x 0.005 kg | G26: #VALUE! | H26: 2800 | I26: SE-LP7680-3Kg | J26: LOCOSC | K26: 45574 | L26: LP3211240 | M26: 71 | O26: ='EQUIPO FEBRERO 2025 1'!AQ26 -> 8 | P26: =O26 -> 8 | Q26: =AK26 -> 8 | R26: =AL26 -> 8 | S26: =AM26 -> 8 | T26: =AN26 -> 8 | Z26: 1 | AE26: 1 | AJ26: ='EQUIPO ENERO 2025'!AP26 -> 8 | AK26: =P26-Z26+AE26+U26 -> 8 | AL26: =Q26-AA26+AF26+V26 -> 8 | AM26: =R26-AB26+AG26+W26 -> 8 | AN26: =S26-AC26+AH26+X26 -> 8 | AO26: =T26-AD26+AI26+Y26 -> 8 | AQ26: =AO26 -> 8 | AS26: 362
A27: =A26+1 -> 22 | B27: BÁSCULA DE MESA | C27: No. 1 | D27: BRECKNELL | E27: SE-7680W | F27: 6 x 0.001 kg | G27: #VALUE! | H27: 2800 | I27: SE-LP7680-6Kg | J27: LOCOSC | K27: 45574 | L27: LP3211240 | M27: 71 | O27: ='EQUIPO FEBRERO 2025 1'!AQ27 -> 10 | P27: =O27 -> 10 | Q27: =AK27 -> 10 | R27: =AL27 -> 10 | S27: =AM27 -> 10 | T27: =AN27 -> 10 | AJ27: ='EQUIPO ENERO 2025'!AP27 -> 10 | AK27: =P27-Z27+AE27+U27 -> 10 | AL27: =Q27-AA27+AF27+V27 -> 10 | AM27: =R27-AB27+AG27+W27 -> 10 | AN27: =S27-AC27+AH27+X27 -> 10 | AO27: =T27-AD27+AI27+Y27 -> 10 | AQ27: =AO27 -> 10
A28: =A27+1 -> 23 | B28: BÁSCULA DE MESA | C28: No. 1 | D28: BRECKNELL | E28: SE-7680W | F28: 15 x 0.002 kg | G28: #VALUE! | H28: 2800 | I28: SE-LP7680-15Kg | J28: LOCOSC | K28: 45574 | L28: LP3211240 | M28: 71 | O28: ='EQUIPO FEBRERO 2025 1'!AQ28 -> 6 | P28: =O28 -> 6 | Q28: =AK28 -> 6 | R28: =AL28 -> 6 | S28: =AM28 -> 6 | T28: =AN28 -> 6 | AJ28: ='EQUIPO ENERO 2025'!AP28 -> 6 | AK28: =P28-Z28+AE28+U28 -> 6 | AL28: =Q28-AA28+AF28+V28 -> 6 | AM28: =R28-AB28+AG28+W28 -> 6 | AN28: =S28-AC28+AH28+X28 -> 6 | AO28: =T28-AD28+AI28+Y28 -> 6 | AQ28: =AO28 -> 6 | AS28: 337/PAPYS
A29: =A28+1 -> 24 | B29: BASCULA DE MESA MODELO SE-7680W | C29: No. 1 | D29: BRECKNELL | E29: SE-7680W | F29: 30 x 0.005 kg | G29: #VALUE! | H29: 3000 | I29: SE-LP7680-30kg | J29: LOCOSC | K29: 45107 | L29: LP230224-1 | M29: 390 | O29: ='EQUIPO FEBRERO 2025 1'!AQ29 -> 5 | P29: =O29 -> 5 | Q29: =AK29 -> 5 | R29: =AL29 -> 5 | S29: =AM29 -> 5 | T29: =AN29 -> 5 | AJ29: ='EQUIPO ENERO 2025'!AP29 -> 5 | AK29: =P29-Z29+AE29+U29 -> 5 | AL29: =Q29-AA29+AF29+V29 -> 5 | AM29: =R29-AB29+AG29+W29 -> 5 | AN29: =S29-AC29+AH29+X29 -> 5 | AO29: =T29-AD29+AI29+Y29 -> 5 | AQ29: =AO29 -> 5
A30: =A29+1 -> 25 | B30: BALANZA ELECTRONIC BALANCE MODELO SE-2003CH DE 2000gx1mg | C30: N/A | D30: ELECTRONIC BALANCE | E30: SE-2003CH | F30: 200 x 1 mg | G30: #VALUE! | H30: 6300 | I30: SE-2003CH | J30: LOCOSC | K30: 45139 | L30: 781781092133 | M30: 419 | O30: ='EQUIPO FEBRERO 2025 1'!AQ30 -> 0 | P30: =O30 -> 0 | Q30: =AK30 -> 0 | R30: =AL30 -> 0 | S30: =AM30 -> 0 | T30: =AN30 -> 0 | AJ30: ='EQUIPO ENERO 2025'!AP30 -> 0 | AK30: =P30-Z30+AE30+U30 -> 0 | AL30: =Q30-AA30+AF30+V30 -> 0 | AM30: =R30-AB30+AG30+W30 -> 0 | AN30: =S30-AC30+AH30+X30 -> 0 | AO30: =T30-AD30+AI30+Y30 -> 0 | AQ30: =AO30 -> 0
A31: =A30+1 -> 26 | B31: BASES DE CELDA DE CARGA PARA CELDAS DE ACEROS DE GUATEMALA | C31: NO. 2 | D31: S/M | E31: S/M | G31: #VALUE! | K31: 45568 | M31: 62 | O31: ='EQUIPO FEBRERO 2025 1'!AQ31 -> 2 | P31: =O31 -> 2 | Q31: =AK31 -> 2 | R31: =AL31 -> 2 | S31: =AM31 -> 2 | T31: =AN31 -> 2 | AJ31: ='EQUIPO ENERO 2025'!AP31 -> 2 | AK31: =P31-Z31+AE31+U31 -> 2 | AL31: =Q31-AA31+AF31+V31 -> 2 | AM31: =R31-AB31+AG31+W31 -> 2 | AN31: =S31-AC31+AH31+X31 -> 2 | AO31: =T31-AD31+AI31+Y31 -> 2 | AQ31: =AO31 -> 2
A32: =A31+1 -> 27 | B32: BASCULA COLGANTE CAPACIDAD 5 t LP7650G | C32: NO.2 | D32: BRECKNELL | E32: SE-7650 | F32: 5 T | G32: #VALUE! | H32: 9500 | I32: SE-LP7650G-5T | J32: SIZEN | K32: 45666 | L32: LK24112701 | M32: 117 | O32: ='EQUIPO FEBRERO 2025 1'!AQ32 -> 1 | P32: =O32 -> 1 | Q32: =AK32 -> 1 | R32: =AL32 -> 1 | S32: =AM32 -> 1 | T32: =AN32 -> 1 | AJ32: ='EQUIPO ENERO 2025'!AP32 -> 1 | AK32: =P32-Z32+AE32+U32 -> 1 | AL32: =Q32-AA32+AF32+V32 -> 1 | AM32: =R32-AB32+AG32+W32 -> 1 | AN32: =S32-AC32+AH32+X32 -> 1 | AO32: =T32-AD32+AI32+Y32 -> 1 | AQ32: =AO32 -> 1
A33: =A32+1 -> 28 | B33: BASCULA COLGANTE CAPACIDAD 10 t LP7650G | C33: No. 2 | D33: BRECKNELL | E33: SE-7650 | F33: 10 t | G33: #VALUE! | H33: Q16,800.00 Consultar primero | I33: SE-LP7650G-10T | J33: LOCOSC | K33: 45107 | L33: LP230224-1 | M33: 393 | O33: ='EQUIPO FEBRERO 2025 1'!AQ33 -> 1 | P33: =O33 -> 1 | Q33: =AK33 -> 1 | R33: =AL33 -> 1 | S33: =AM33 -> 1 | T33: =AN33 -> 1 | AJ33: ='EQUIPO ENERO 2025'!AP33 -> 1 | AK33: =P33-Z33+AE33+U33 -> 1 | AL33: =Q33-AA33+AF33+V33 -> 1 | AM33: =R33-AB33+AG33+W33 -> 1 | AN33: =S33-AC33+AH33+X33 -> 1 | AO33: =T33-AD33+AI33+Y33 -> 1 | AQ33: =AO33 -> 1
A34: =A33+1 -> 29 | B34: BASCULA COLGANTE CAPACIDAD 300kg LP7652G | C34: No. 1 | D34: BRECKNELL | E34: SE-7652 | F34: 300 x 0.1 kg | G34: #VALUE! | H34: 650 | I34: SE-COLG-LP7652G | J34: LOCOSC | K34: 45107 | L34: LP230224-1 | M34: 389 | O34: ='EQUIPO FEBRERO 2025 1'!AQ34 -> 11 | P34: =O34 -> 11 | Q34: =AK34 -> 11 | R34: =AL34 -> 11 | S34: =AM34 -> 11 | T34: =AN34 -> 11 | AJ34: ='EQUIPO ENERO 2025'!AP34 -> 11 | AK34: =P34-Z34+AE34+U34 -> 11 | AL34: =Q34-AA34+AF34+V34 -> 11 | AM34: =R34-AB34+AG34+W34 -> 11 | AN34: =S34-AC34+AH34+X34 -> 11 | AO34: =T34-AD34+AI34+Y34 -> 11 | AQ34: =AO34 -> 11
A35: =A34+1 -> 30 | B35: BASCULA COLGANTE PANTALLA LED DE 5 DIGITOS | C35: No. 1 | D35: BRECKNELL | E35: SE-7561 | F35: 300 x 0.1 kg | G35: #VALUE! | H35: 1800 | I35: SE-LP7561E | J35: LOCOSC | K35: 44592 | O35: ='EQUIPO FEBRERO 2025 1'!AQ35 -> 6 | P35: =O35 -> 6 | Q35: =AK35 -> 6 | R35: =AL35 -> 6 | S35: =AM35 -> 6 | T35: =AN35 -> 6 | AJ35: ='EQUIPO ENERO 2025'!AP35 -> 6 | AK35: =P35-Z35+AE35+U35 -> 6 | AL35: =Q35-AA35+AF35+V35 -> 6 | AM35: =R35-AB35+AG35+W35 -> 6 | AN35: =S35-AC35+AH35+X35 -> 6 | AO35: =T35-AD35+AI35+Y35 -> 6 | AQ35: =AO35 -> 6
A36: =A35+1 -> 31 | B36: BASCULA DE MESA CAPACIDAD 30kgx1g | C36: No. 1 | D36: ELECTRONIC BALANCE | E36: SE-WT300001X | F36: 30 kg x 1 g | G36: #VALUE! | H36: 3400 | I36: SE-WT300001X | J36: LOCOSC | K36: 45107 | L36: LP230224-1 | M36: 393 | O36: ='EQUIPO FEBRERO 2025 1'!AQ36 -> 4 | P36: =O36 -> 4 | Q36: =AK36 -> 4 | R36: =AL36 -> 4 | S36: =AM36 -> 4 | T36: =AN36 -> 4 | AJ36: ='EQUIPO ENERO 2025'!AP36 -> 4 | AK36: =P36-Z36+AE36+U36 -> 4 | AL36: =Q36-AA36+AF36+V36 -> 4 | AM36: =R36-AB36+AG36+W36 -> 4 | AN36: =S36-AC36+AH36+X36 -> 4 | AO36: =T36-AD36+AI36+Y36 -> 4 | AQ36: =AO36 -> 4
A37: =A36+1 -> 32 | B37: BASCULA DE MESA MODELO SE-Y2-208 CAPACIDAD 40kg X 5g | C37: No. 1 | D37: TECNO SCALE | E37: SE-Y2-208 | F37: 40 kg x 5 g | G37: #VALUE! | H37: 550 | I37: SE-Y2-208 | J37: LOCOSC | K37: 45328 | L37: LP230224-1 | M37: 32 | N37: AUTORIZADO POR WILLIAM SÁNCHEZ | O37: ='EQUIPO FEBRERO 2025 1'!AQ37 -> 12 | P37: =O37 -> 12 | Q37: =AK37 -> 12 | R37: =AL37 -> 12 | S37: =AM37 -> 12 | T37: =AN37 -> 12 | Z37: 12 | AE37: 12 | AJ37: ='EQUIPO ENERO 2025'!AP37 -> 14 | AK37: =P37-Z37+AE37+U37 -> 12 | AL37: =Q37-AA37+AF37+V37 -> 12 | AM37: =R37-AB37+AG37+W37 -> 12 | AN37: =S37-AC37+AH37+X37 -> 12 | AO37: =T37-AD37+AI37+Y37 -> 12 | AQ37: =AO37 -> 12
A38: =A37+1 -> 33 | B38: BASCULA DE PISO ACERO INOXIDABLE CAPACIDAD 150kg DE 40X50 | C38: No. 1 | D38: BRECKNELL | E38: SE-7610W | F38: 150 x 0.02 kg | G38: #VALUE! | H38: 7500 | I38: SE-7510W-150kg | J38: LOCOSC | K38: 45107 | L38: LP230224-1 | M38: 392 | N38: ACEROS | O38: ='EQUIPO FEBRERO 2025 1'!AQ38 -> 5 | P38: =O38 -> 5 | Q38: =AK38 -> 5 | R38: =AL38 -> 5 | S38: =AM38 -> 5 | T38: =AN38 -> 5 | AJ38: ='EQUIPO ENERO 2025'!AP38 -> 5 | AK38: =P38-Z38+AE38+U38 -> 5 | AL38: =Q38-AA38+AF38+V38 -> 5 | AM38: =R38-AB38+AG38+W38 -> 5 | AN38: =S38-AC38+AH38+X38 -> 5 | AO38: =T38-AD38+AI38+Y38 -> 5 | AP38: 1 | AQ38: =AO38 -> 5
